[2024-10-16T00:00:17.648+0000] {local_task_job_runner.py:120} INFO - ::group::Pre task execution logs
[2024-10-16T00:00:18.658+0000] {taskinstance.py:2076} INFO - Dependencies all met for dep_context=non-requeueable deps ti=<TaskInstance: airbyte_sync_tables_postgres.sync_schemas.SSO.airbyte_trigger_sync_SSO scheduled__2024-10-15T00:00:00+00:00 [queued]>
[2024-10-16T00:00:18.837+0000] {taskinstance.py:2076} INFO - Dependencies all met for dep_context=requeueable deps ti=<TaskInstance: airbyte_sync_tables_postgres.sync_schemas.SSO.airbyte_trigger_sync_SSO scheduled__2024-10-15T00:00:00+00:00 [queued]>
[2024-10-16T00:00:18.841+0000] {taskinstance.py:2306} INFO - Starting attempt 1 of 1
[2024-10-16T00:00:19.092+0000] {taskinstance.py:2330} INFO - Executing <Task(AirbyteTriggerSyncOperator): sync_schemas.SSO.airbyte_trigger_sync_SSO> on 2024-10-15 00:00:00+00:00
[2024-10-16T00:00:19.234+0000] {standard_task_runner.py:90} INFO - Running: ['***', 'tasks', 'run', 'airbyte_sync_tables_postgres', 'sync_schemas.SSO.airbyte_trigger_sync_SSO', 'scheduled__2024-10-15T00:00:00+00:00', '--job-id', '40', '--raw', '--subdir', 'DAGS_FOLDER/airbyte_sync_tables_postgres.py', '--cfg-path', '/tmp/tmp_kiwlldx']
[2024-10-16T00:00:19.249+0000] {standard_task_runner.py:91} INFO - Job 40: Subtask sync_schemas.SSO.airbyte_trigger_sync_SSO
[2024-10-16T00:00:19.328+0000] {logging_mixin.py:188} WARNING - /home/***/.local/lib/python3.12/site-packages/***/task/task_runner/standard_task_runner.py:62 DeprecationWarning: This process (pid=15263) is multi-threaded, use of fork() may lead to deadlocks in the child.
[2024-10-16T00:00:19.332+0000] {standard_task_runner.py:64} INFO - Started process 15278 to run task
[2024-10-16T00:00:20.830+0000] {task_command.py:426} INFO - Running <TaskInstance: airbyte_sync_tables_postgres.sync_schemas.SSO.airbyte_trigger_sync_SSO scheduled__2024-10-15T00:00:00+00:00 [running]> on host efbb3a47dac9
[2024-10-16T00:00:22.839+0000] {taskinstance.py:2648} INFO - Exporting env vars: AIRFLOW_CTX_DAG_OWNER='vizentec-engdados' AIRFLOW_CTX_DAG_ID='airbyte_sync_tables_postgres' AIRFLOW_CTX_TASK_ID='sync_schemas.SSO.airbyte_trigger_sync_SSO' AIRFLOW_CTX_EXECUTION_DATE='2024-10-15T00:00:00+00:00' AIRFLOW_CTX_TRY_NUMBER='1' AIRFLOW_CTX_DAG_RUN_ID='scheduled__2024-10-15T00:00:00+00:00'
[2024-10-16T00:00:22.848+0000] {taskinstance.py:430} INFO - ::endgroup::
[2024-10-16T00:00:24.429+0000] {base.py:84} INFO - Using connection ID 'airbyte_conn' for task execution.
[2024-10-16T00:00:25.966+0000] {http.py:243} WARNING - HTTPConnectionPool(host='airbyte.vizentec.com.br', port=80): Max retries exceeded with url: /api/v1/connections/sync (Caused by NameResolutionError("<urllib3.connection.HTTPConnection object at 0x7fd81ef67d70>: Failed to resolve 'airbyte.vizentec.com.br' ([Errno -2] Name or service not known)")) Tenacity will retry to execute the operation
[2024-10-16T00:00:25.971+0000] {taskinstance.py:441} INFO - ::group::Post task execution logs
[2024-10-16T00:00:25.976+0000] {taskinstance.py:2905} ERROR - Task failed with exception
Traceback (most recent call last):
  File "/home/airflow/.local/lib/python3.12/site-packages/urllib3/connection.py", line 203, in _new_conn
    sock = connection.create_connection(
           ^^^^^^^^^^^^^^^^^^^^^^^^^^^^^
  File "/home/airflow/.local/lib/python3.12/site-packages/urllib3/util/connection.py", line 60, in create_connection
    for res in socket.getaddrinfo(host, port, family, socket.SOCK_STREAM):
               ^^^^^^^^^^^^^^^^^^^^^^^^^^^^^^^^^^^^^^^^^^^^^^^^^^^^^^^^^^
  File "/usr/local/lib/python3.12/socket.py", line 964, in getaddrinfo
    for res in _socket.getaddrinfo(host, port, family, type, proto, flags):
               ^^^^^^^^^^^^^^^^^^^^^^^^^^^^^^^^^^^^^^^^^^^^^^^^^^^^^^^^^^^
socket.gaierror: [Errno -2] Name or service not known

The above exception was the direct cause of the following exception:

Traceback (most recent call last):
  File "/home/airflow/.local/lib/python3.12/site-packages/urllib3/connectionpool.py", line 791, in urlopen
    response = self._make_request(
               ^^^^^^^^^^^^^^^^^^^
  File "/home/airflow/.local/lib/python3.12/site-packages/urllib3/connectionpool.py", line 497, in _make_request
    conn.request(
  File "/home/airflow/.local/lib/python3.12/site-packages/urllib3/connection.py", line 395, in request
    self.endheaders()
  File "/usr/local/lib/python3.12/http/client.py", line 1331, in endheaders
    self._send_output(message_body, encode_chunked=encode_chunked)
  File "/usr/local/lib/python3.12/http/client.py", line 1091, in _send_output
    self.send(msg)
  File "/usr/local/lib/python3.12/http/client.py", line 1035, in send
    self.connect()
  File "/home/airflow/.local/lib/python3.12/site-packages/urllib3/connection.py", line 243, in connect
    self.sock = self._new_conn()
                ^^^^^^^^^^^^^^^^
  File "/home/airflow/.local/lib/python3.12/site-packages/urllib3/connection.py", line 210, in _new_conn
    raise NameResolutionError(self.host, self, e) from e
urllib3.exceptions.NameResolutionError: <urllib3.connection.HTTPConnection object at 0x7fd81ef67d70>: Failed to resolve 'airbyte.vizentec.com.br' ([Errno -2] Name or service not known)

The above exception was the direct cause of the following exception:

Traceback (most recent call last):
  File "/home/airflow/.local/lib/python3.12/site-packages/requests/adapters.py", line 667, in send
    resp = conn.urlopen(
           ^^^^^^^^^^^^^
  File "/home/airflow/.local/lib/python3.12/site-packages/urllib3/connectionpool.py", line 845, in urlopen
    retries = retries.increment(
              ^^^^^^^^^^^^^^^^^^
  File "/home/airflow/.local/lib/python3.12/site-packages/urllib3/util/retry.py", line 515, in increment
    raise MaxRetryError(_pool, url, reason) from reason  # type: ignore[arg-type]
    ^^^^^^^^^^^^^^^^^^^^^^^^^^^^^^^^^^^^^^^^^^^^^^^^^^^
urllib3.exceptions.MaxRetryError: HTTPConnectionPool(host='airbyte.vizentec.com.br', port=80): Max retries exceeded with url: /api/v1/connections/sync (Caused by NameResolutionError("<urllib3.connection.HTTPConnection object at 0x7fd81ef67d70>: Failed to resolve 'airbyte.vizentec.com.br' ([Errno -2] Name or service not known)"))

During handling of the above exception, another exception occurred:

Traceback (most recent call last):
  File "/home/airflow/.local/lib/python3.12/site-packages/airflow/models/taskinstance.py", line 465, in _execute_task
    result = _execute_callable(context=context, **execute_callable_kwargs)
             ^^^^^^^^^^^^^^^^^^^^^^^^^^^^^^^^^^^^^^^^^^^^^^^^^^^^^^^^^^^^^
  File "/home/airflow/.local/lib/python3.12/site-packages/airflow/models/taskinstance.py", line 432, in _execute_callable
    return execute_callable(context=context, **execute_callable_kwargs)
           ^^^^^^^^^^^^^^^^^^^^^^^^^^^^^^^^^^^^^^^^^^^^^^^^^^^^^^^^^^^^
  File "/home/airflow/.local/lib/python3.12/site-packages/airflow/models/baseoperator.py", line 401, in wrapper
    return func(self, *args, **kwargs)
           ^^^^^^^^^^^^^^^^^^^^^^^^^^^
  File "/home/airflow/.local/lib/python3.12/site-packages/airflow/providers/airbyte/operators/airbyte.py", line 86, in execute
    job_object = hook.submit_sync_connection(connection_id=self.connection_id)
                 ^^^^^^^^^^^^^^^^^^^^^^^^^^^^^^^^^^^^^^^^^^^^^^^^^^^^^^^^^^^^^
  File "/home/airflow/.local/lib/python3.12/site-packages/airflow/providers/airbyte/hooks/airbyte.py", line 185, in submit_sync_connection
    return self.run(
           ^^^^^^^^^
  File "/home/airflow/.local/lib/python3.12/site-packages/airflow/providers/http/hooks/http.py", line 188, in run
    return self.run_and_check(session, prepped_request, extra_options)
           ^^^^^^^^^^^^^^^^^^^^^^^^^^^^^^^^^^^^^^^^^^^^^^^^^^^^^^^^^^^
  File "/home/airflow/.local/lib/python3.12/site-packages/airflow/providers/http/hooks/http.py", line 244, in run_and_check
    raise ex
  File "/home/airflow/.local/lib/python3.12/site-packages/airflow/providers/http/hooks/http.py", line 236, in run_and_check
    response = session.send(prepped_request, **send_kwargs)
               ^^^^^^^^^^^^^^^^^^^^^^^^^^^^^^^^^^^^^^^^^^^^
  File "/home/airflow/.local/lib/python3.12/site-packages/requests/sessions.py", line 703, in send
    r = adapter.send(request, **kwargs)
        ^^^^^^^^^^^^^^^^^^^^^^^^^^^^^^^
  File "/home/airflow/.local/lib/python3.12/site-packages/requests/adapters.py", line 700, in send
    raise ConnectionError(e, request=request)
requests.exceptions.ConnectionError: HTTPConnectionPool(host='airbyte.vizentec.com.br', port=80): Max retries exceeded with url: /api/v1/connections/sync (Caused by NameResolutionError("<urllib3.connection.HTTPConnection object at 0x7fd81ef67d70>: Failed to resolve 'airbyte.vizentec.com.br' ([Errno -2] Name or service not known)"))
[2024-10-16T00:00:26.360+0000] {taskinstance.py:1206} INFO - Marking task as FAILED. dag_id=airbyte_sync_tables_postgres, task_id=sync_schemas.SSO.airbyte_trigger_sync_SSO, run_id=scheduled__2024-10-15T00:00:00+00:00, execution_date=20241015T000000, start_date=20241016T000018, end_date=20241016T000026
[2024-10-16T00:00:26.624+0000] {standard_task_runner.py:110} ERROR - Failed to execute job 40 for task sync_schemas.SSO.airbyte_trigger_sync_SSO (HTTPConnectionPool(host='airbyte.vizentec.com.br', port=80): Max retries exceeded with url: /api/v1/connections/sync (Caused by NameResolutionError("<urllib3.connection.HTTPConnection object at 0x7fd81ef67d70>: Failed to resolve 'airbyte.vizentec.com.br' ([Errno -2] Name or service not known)")); 15278)
[2024-10-16T00:00:26.668+0000] {local_task_job_runner.py:243} INFO - Task exited with return code 1
[2024-10-16T00:00:27.230+0000] {taskinstance.py:3503} INFO - 0 downstream tasks scheduled from follow-on schedule check
[2024-10-16T00:00:27.265+0000] {local_task_job_runner.py:222} INFO - ::endgroup::
