[2024-11-07T00:00:22.248+0000] {processor.py:161} INFO - Started process (PID=8335) to work on /opt/airflow/dags/airbyte_sync_fluxos.py
[2024-11-07T00:00:22.250+0000] {processor.py:830} INFO - Processing file /opt/airflow/dags/airbyte_sync_fluxos.py for tasks to queue
[2024-11-07T00:00:22.252+0000] {logging_mixin.py:188} INFO - [2024-11-07T00:00:22.252+0000] {dagbag.py:545} INFO - Filling up the DagBag from /opt/airflow/dags/airbyte_sync_fluxos.py
[2024-11-07T00:00:22.328+0000] {logging_mixin.py:188} INFO - [2024-11-07T00:00:22.318+0000] {dagbag.py:355} ERROR - Failed to import: /opt/airflow/dags/airbyte_sync_fluxos.py
Traceback (most recent call last):
  File "/home/airflow/.local/lib/python3.12/site-packages/airflow/models/dagbag.py", line 351, in parse
    loader.exec_module(new_module)
  File "<frozen importlib._bootstrap_external>", line 995, in exec_module
  File "<frozen importlib._bootstrap>", line 488, in _call_with_frames_removed
  File "/opt/airflow/dags/airbyte_sync_fluxos.py", line 11, in <module>
    from kafka import KafkaConsumer
  File "/home/airflow/.local/lib/python3.12/site-packages/kafka/__init__.py", line 23, in <module>
    from kafka.consumer import KafkaConsumer
  File "/home/airflow/.local/lib/python3.12/site-packages/kafka/consumer/__init__.py", line 3, in <module>
    from kafka.consumer.group import KafkaConsumer
  File "/home/airflow/.local/lib/python3.12/site-packages/kafka/consumer/group.py", line 13, in <module>
    from kafka.consumer.fetcher import Fetcher
  File "/home/airflow/.local/lib/python3.12/site-packages/kafka/consumer/fetcher.py", line 19, in <module>
    from kafka.record import MemoryRecords
  File "/home/airflow/.local/lib/python3.12/site-packages/kafka/record/__init__.py", line 1, in <module>
    from kafka.record.memory_records import MemoryRecords, MemoryRecordsBuilder
  File "/home/airflow/.local/lib/python3.12/site-packages/kafka/record/memory_records.py", line 27, in <module>
    from kafka.record.legacy_records import LegacyRecordBatch, LegacyRecordBatchBuilder
  File "/home/airflow/.local/lib/python3.12/site-packages/kafka/record/legacy_records.py", line 50, in <module>
    from kafka.codec import (
  File "/home/airflow/.local/lib/python3.12/site-packages/kafka/codec.py", line 9, in <module>
    from kafka.vendor.six.moves import range
ModuleNotFoundError: No module named 'kafka.vendor.six.moves'
[2024-11-07T00:00:22.330+0000] {processor.py:842} WARNING - No viable dags retrieved from /opt/airflow/dags/airbyte_sync_fluxos.py
[2024-11-07T00:00:22.359+0000] {processor.py:183} INFO - Processing /opt/airflow/dags/airbyte_sync_fluxos.py took 0.119 seconds
[2024-11-07T00:00:53.018+0000] {processor.py:161} INFO - Started process (PID=8357) to work on /opt/airflow/dags/airbyte_sync_fluxos.py
[2024-11-07T00:00:53.020+0000] {processor.py:830} INFO - Processing file /opt/airflow/dags/airbyte_sync_fluxos.py for tasks to queue
[2024-11-07T00:00:53.023+0000] {logging_mixin.py:188} INFO - [2024-11-07T00:00:53.022+0000] {dagbag.py:545} INFO - Filling up the DagBag from /opt/airflow/dags/airbyte_sync_fluxos.py
[2024-11-07T00:00:53.103+0000] {logging_mixin.py:188} INFO - [2024-11-07T00:00:53.094+0000] {dagbag.py:355} ERROR - Failed to import: /opt/airflow/dags/airbyte_sync_fluxos.py
Traceback (most recent call last):
  File "/home/airflow/.local/lib/python3.12/site-packages/airflow/models/dagbag.py", line 351, in parse
    loader.exec_module(new_module)
  File "<frozen importlib._bootstrap_external>", line 995, in exec_module
  File "<frozen importlib._bootstrap>", line 488, in _call_with_frames_removed
  File "/opt/airflow/dags/airbyte_sync_fluxos.py", line 11, in <module>
    from kafka import KafkaConsumer
  File "/home/airflow/.local/lib/python3.12/site-packages/kafka/__init__.py", line 23, in <module>
    from kafka.consumer import KafkaConsumer
  File "/home/airflow/.local/lib/python3.12/site-packages/kafka/consumer/__init__.py", line 3, in <module>
    from kafka.consumer.group import KafkaConsumer
  File "/home/airflow/.local/lib/python3.12/site-packages/kafka/consumer/group.py", line 13, in <module>
    from kafka.consumer.fetcher import Fetcher
  File "/home/airflow/.local/lib/python3.12/site-packages/kafka/consumer/fetcher.py", line 19, in <module>
    from kafka.record import MemoryRecords
  File "/home/airflow/.local/lib/python3.12/site-packages/kafka/record/__init__.py", line 1, in <module>
    from kafka.record.memory_records import MemoryRecords, MemoryRecordsBuilder
  File "/home/airflow/.local/lib/python3.12/site-packages/kafka/record/memory_records.py", line 27, in <module>
    from kafka.record.legacy_records import LegacyRecordBatch, LegacyRecordBatchBuilder
  File "/home/airflow/.local/lib/python3.12/site-packages/kafka/record/legacy_records.py", line 50, in <module>
    from kafka.codec import (
  File "/home/airflow/.local/lib/python3.12/site-packages/kafka/codec.py", line 9, in <module>
    from kafka.vendor.six.moves import range
ModuleNotFoundError: No module named 'kafka.vendor.six.moves'
[2024-11-07T00:00:53.105+0000] {processor.py:842} WARNING - No viable dags retrieved from /opt/airflow/dags/airbyte_sync_fluxos.py
[2024-11-07T00:00:53.138+0000] {processor.py:183} INFO - Processing /opt/airflow/dags/airbyte_sync_fluxos.py took 0.127 seconds
[2024-11-07T00:01:23.577+0000] {processor.py:161} INFO - Started process (PID=8379) to work on /opt/airflow/dags/airbyte_sync_fluxos.py
[2024-11-07T00:01:23.579+0000] {processor.py:830} INFO - Processing file /opt/airflow/dags/airbyte_sync_fluxos.py for tasks to queue
[2024-11-07T00:01:23.582+0000] {logging_mixin.py:188} INFO - [2024-11-07T00:01:23.581+0000] {dagbag.py:545} INFO - Filling up the DagBag from /opt/airflow/dags/airbyte_sync_fluxos.py
[2024-11-07T00:01:23.664+0000] {logging_mixin.py:188} INFO - [2024-11-07T00:01:23.655+0000] {dagbag.py:355} ERROR - Failed to import: /opt/airflow/dags/airbyte_sync_fluxos.py
Traceback (most recent call last):
  File "/home/airflow/.local/lib/python3.12/site-packages/airflow/models/dagbag.py", line 351, in parse
    loader.exec_module(new_module)
  File "<frozen importlib._bootstrap_external>", line 995, in exec_module
  File "<frozen importlib._bootstrap>", line 488, in _call_with_frames_removed
  File "/opt/airflow/dags/airbyte_sync_fluxos.py", line 11, in <module>
    from kafka import KafkaConsumer
  File "/home/airflow/.local/lib/python3.12/site-packages/kafka/__init__.py", line 23, in <module>
    from kafka.consumer import KafkaConsumer
  File "/home/airflow/.local/lib/python3.12/site-packages/kafka/consumer/__init__.py", line 3, in <module>
    from kafka.consumer.group import KafkaConsumer
  File "/home/airflow/.local/lib/python3.12/site-packages/kafka/consumer/group.py", line 13, in <module>
    from kafka.consumer.fetcher import Fetcher
  File "/home/airflow/.local/lib/python3.12/site-packages/kafka/consumer/fetcher.py", line 19, in <module>
    from kafka.record import MemoryRecords
  File "/home/airflow/.local/lib/python3.12/site-packages/kafka/record/__init__.py", line 1, in <module>
    from kafka.record.memory_records import MemoryRecords, MemoryRecordsBuilder
  File "/home/airflow/.local/lib/python3.12/site-packages/kafka/record/memory_records.py", line 27, in <module>
    from kafka.record.legacy_records import LegacyRecordBatch, LegacyRecordBatchBuilder
  File "/home/airflow/.local/lib/python3.12/site-packages/kafka/record/legacy_records.py", line 50, in <module>
    from kafka.codec import (
  File "/home/airflow/.local/lib/python3.12/site-packages/kafka/codec.py", line 9, in <module>
    from kafka.vendor.six.moves import range
ModuleNotFoundError: No module named 'kafka.vendor.six.moves'
[2024-11-07T00:01:23.666+0000] {processor.py:842} WARNING - No viable dags retrieved from /opt/airflow/dags/airbyte_sync_fluxos.py
[2024-11-07T00:01:23.696+0000] {processor.py:183} INFO - Processing /opt/airflow/dags/airbyte_sync_fluxos.py took 0.124 seconds
[2024-11-07T00:01:54.212+0000] {processor.py:161} INFO - Started process (PID=8401) to work on /opt/airflow/dags/airbyte_sync_fluxos.py
[2024-11-07T00:01:54.214+0000] {processor.py:830} INFO - Processing file /opt/airflow/dags/airbyte_sync_fluxos.py for tasks to queue
[2024-11-07T00:01:54.217+0000] {logging_mixin.py:188} INFO - [2024-11-07T00:01:54.216+0000] {dagbag.py:545} INFO - Filling up the DagBag from /opt/airflow/dags/airbyte_sync_fluxos.py
[2024-11-07T00:01:54.300+0000] {logging_mixin.py:188} INFO - [2024-11-07T00:01:54.289+0000] {dagbag.py:355} ERROR - Failed to import: /opt/airflow/dags/airbyte_sync_fluxos.py
Traceback (most recent call last):
  File "/home/airflow/.local/lib/python3.12/site-packages/airflow/models/dagbag.py", line 351, in parse
    loader.exec_module(new_module)
  File "<frozen importlib._bootstrap_external>", line 995, in exec_module
  File "<frozen importlib._bootstrap>", line 488, in _call_with_frames_removed
  File "/opt/airflow/dags/airbyte_sync_fluxos.py", line 11, in <module>
    from kafka import KafkaConsumer
  File "/home/airflow/.local/lib/python3.12/site-packages/kafka/__init__.py", line 23, in <module>
    from kafka.consumer import KafkaConsumer
  File "/home/airflow/.local/lib/python3.12/site-packages/kafka/consumer/__init__.py", line 3, in <module>
    from kafka.consumer.group import KafkaConsumer
  File "/home/airflow/.local/lib/python3.12/site-packages/kafka/consumer/group.py", line 13, in <module>
    from kafka.consumer.fetcher import Fetcher
  File "/home/airflow/.local/lib/python3.12/site-packages/kafka/consumer/fetcher.py", line 19, in <module>
    from kafka.record import MemoryRecords
  File "/home/airflow/.local/lib/python3.12/site-packages/kafka/record/__init__.py", line 1, in <module>
    from kafka.record.memory_records import MemoryRecords, MemoryRecordsBuilder
  File "/home/airflow/.local/lib/python3.12/site-packages/kafka/record/memory_records.py", line 27, in <module>
    from kafka.record.legacy_records import LegacyRecordBatch, LegacyRecordBatchBuilder
  File "/home/airflow/.local/lib/python3.12/site-packages/kafka/record/legacy_records.py", line 50, in <module>
    from kafka.codec import (
  File "/home/airflow/.local/lib/python3.12/site-packages/kafka/codec.py", line 9, in <module>
    from kafka.vendor.six.moves import range
ModuleNotFoundError: No module named 'kafka.vendor.six.moves'
[2024-11-07T00:01:54.302+0000] {processor.py:842} WARNING - No viable dags retrieved from /opt/airflow/dags/airbyte_sync_fluxos.py
[2024-11-07T00:01:54.328+0000] {processor.py:183} INFO - Processing /opt/airflow/dags/airbyte_sync_fluxos.py took 0.122 seconds
[2024-11-07T00:02:24.873+0000] {processor.py:161} INFO - Started process (PID=8423) to work on /opt/airflow/dags/airbyte_sync_fluxos.py
[2024-11-07T00:02:24.875+0000] {processor.py:830} INFO - Processing file /opt/airflow/dags/airbyte_sync_fluxos.py for tasks to queue
[2024-11-07T00:02:24.879+0000] {logging_mixin.py:188} INFO - [2024-11-07T00:02:24.879+0000] {dagbag.py:545} INFO - Filling up the DagBag from /opt/airflow/dags/airbyte_sync_fluxos.py
[2024-11-07T00:02:24.970+0000] {logging_mixin.py:188} INFO - [2024-11-07T00:02:24.960+0000] {dagbag.py:355} ERROR - Failed to import: /opt/airflow/dags/airbyte_sync_fluxos.py
Traceback (most recent call last):
  File "/home/airflow/.local/lib/python3.12/site-packages/airflow/models/dagbag.py", line 351, in parse
    loader.exec_module(new_module)
  File "<frozen importlib._bootstrap_external>", line 995, in exec_module
  File "<frozen importlib._bootstrap>", line 488, in _call_with_frames_removed
  File "/opt/airflow/dags/airbyte_sync_fluxos.py", line 11, in <module>
    from kafka import KafkaConsumer
  File "/home/airflow/.local/lib/python3.12/site-packages/kafka/__init__.py", line 23, in <module>
    from kafka.consumer import KafkaConsumer
  File "/home/airflow/.local/lib/python3.12/site-packages/kafka/consumer/__init__.py", line 3, in <module>
    from kafka.consumer.group import KafkaConsumer
  File "/home/airflow/.local/lib/python3.12/site-packages/kafka/consumer/group.py", line 13, in <module>
    from kafka.consumer.fetcher import Fetcher
  File "/home/airflow/.local/lib/python3.12/site-packages/kafka/consumer/fetcher.py", line 19, in <module>
    from kafka.record import MemoryRecords
  File "/home/airflow/.local/lib/python3.12/site-packages/kafka/record/__init__.py", line 1, in <module>
    from kafka.record.memory_records import MemoryRecords, MemoryRecordsBuilder
  File "/home/airflow/.local/lib/python3.12/site-packages/kafka/record/memory_records.py", line 27, in <module>
    from kafka.record.legacy_records import LegacyRecordBatch, LegacyRecordBatchBuilder
  File "/home/airflow/.local/lib/python3.12/site-packages/kafka/record/legacy_records.py", line 50, in <module>
    from kafka.codec import (
  File "/home/airflow/.local/lib/python3.12/site-packages/kafka/codec.py", line 9, in <module>
    from kafka.vendor.six.moves import range
ModuleNotFoundError: No module named 'kafka.vendor.six.moves'
[2024-11-07T00:02:24.972+0000] {processor.py:842} WARNING - No viable dags retrieved from /opt/airflow/dags/airbyte_sync_fluxos.py
[2024-11-07T00:02:25.002+0000] {processor.py:183} INFO - Processing /opt/airflow/dags/airbyte_sync_fluxos.py took 0.137 seconds
[2024-11-07T00:02:55.536+0000] {processor.py:161} INFO - Started process (PID=8445) to work on /opt/airflow/dags/airbyte_sync_fluxos.py
[2024-11-07T00:02:55.538+0000] {processor.py:830} INFO - Processing file /opt/airflow/dags/airbyte_sync_fluxos.py for tasks to queue
[2024-11-07T00:02:55.540+0000] {logging_mixin.py:188} INFO - [2024-11-07T00:02:55.540+0000] {dagbag.py:545} INFO - Filling up the DagBag from /opt/airflow/dags/airbyte_sync_fluxos.py
[2024-11-07T00:02:55.608+0000] {logging_mixin.py:188} INFO - [2024-11-07T00:02:55.598+0000] {dagbag.py:355} ERROR - Failed to import: /opt/airflow/dags/airbyte_sync_fluxos.py
Traceback (most recent call last):
  File "/home/airflow/.local/lib/python3.12/site-packages/airflow/models/dagbag.py", line 351, in parse
    loader.exec_module(new_module)
  File "<frozen importlib._bootstrap_external>", line 995, in exec_module
  File "<frozen importlib._bootstrap>", line 488, in _call_with_frames_removed
  File "/opt/airflow/dags/airbyte_sync_fluxos.py", line 11, in <module>
    from kafka import KafkaConsumer
  File "/home/airflow/.local/lib/python3.12/site-packages/kafka/__init__.py", line 23, in <module>
    from kafka.consumer import KafkaConsumer
  File "/home/airflow/.local/lib/python3.12/site-packages/kafka/consumer/__init__.py", line 3, in <module>
    from kafka.consumer.group import KafkaConsumer
  File "/home/airflow/.local/lib/python3.12/site-packages/kafka/consumer/group.py", line 13, in <module>
    from kafka.consumer.fetcher import Fetcher
  File "/home/airflow/.local/lib/python3.12/site-packages/kafka/consumer/fetcher.py", line 19, in <module>
    from kafka.record import MemoryRecords
  File "/home/airflow/.local/lib/python3.12/site-packages/kafka/record/__init__.py", line 1, in <module>
    from kafka.record.memory_records import MemoryRecords, MemoryRecordsBuilder
  File "/home/airflow/.local/lib/python3.12/site-packages/kafka/record/memory_records.py", line 27, in <module>
    from kafka.record.legacy_records import LegacyRecordBatch, LegacyRecordBatchBuilder
  File "/home/airflow/.local/lib/python3.12/site-packages/kafka/record/legacy_records.py", line 50, in <module>
    from kafka.codec import (
  File "/home/airflow/.local/lib/python3.12/site-packages/kafka/codec.py", line 9, in <module>
    from kafka.vendor.six.moves import range
ModuleNotFoundError: No module named 'kafka.vendor.six.moves'
[2024-11-07T00:02:55.609+0000] {processor.py:842} WARNING - No viable dags retrieved from /opt/airflow/dags/airbyte_sync_fluxos.py
[2024-11-07T00:02:55.635+0000] {processor.py:183} INFO - Processing /opt/airflow/dags/airbyte_sync_fluxos.py took 0.106 seconds
[2024-11-07T00:03:26.179+0000] {processor.py:161} INFO - Started process (PID=8467) to work on /opt/airflow/dags/airbyte_sync_fluxos.py
[2024-11-07T00:03:26.180+0000] {processor.py:830} INFO - Processing file /opt/airflow/dags/airbyte_sync_fluxos.py for tasks to queue
[2024-11-07T00:03:26.183+0000] {logging_mixin.py:188} INFO - [2024-11-07T00:03:26.183+0000] {dagbag.py:545} INFO - Filling up the DagBag from /opt/airflow/dags/airbyte_sync_fluxos.py
[2024-11-07T00:03:26.249+0000] {logging_mixin.py:188} INFO - [2024-11-07T00:03:26.240+0000] {dagbag.py:355} ERROR - Failed to import: /opt/airflow/dags/airbyte_sync_fluxos.py
Traceback (most recent call last):
  File "/home/airflow/.local/lib/python3.12/site-packages/airflow/models/dagbag.py", line 351, in parse
    loader.exec_module(new_module)
  File "<frozen importlib._bootstrap_external>", line 995, in exec_module
  File "<frozen importlib._bootstrap>", line 488, in _call_with_frames_removed
  File "/opt/airflow/dags/airbyte_sync_fluxos.py", line 11, in <module>
    from kafka import KafkaConsumer
  File "/home/airflow/.local/lib/python3.12/site-packages/kafka/__init__.py", line 23, in <module>
    from kafka.consumer import KafkaConsumer
  File "/home/airflow/.local/lib/python3.12/site-packages/kafka/consumer/__init__.py", line 3, in <module>
    from kafka.consumer.group import KafkaConsumer
  File "/home/airflow/.local/lib/python3.12/site-packages/kafka/consumer/group.py", line 13, in <module>
    from kafka.consumer.fetcher import Fetcher
  File "/home/airflow/.local/lib/python3.12/site-packages/kafka/consumer/fetcher.py", line 19, in <module>
    from kafka.record import MemoryRecords
  File "/home/airflow/.local/lib/python3.12/site-packages/kafka/record/__init__.py", line 1, in <module>
    from kafka.record.memory_records import MemoryRecords, MemoryRecordsBuilder
  File "/home/airflow/.local/lib/python3.12/site-packages/kafka/record/memory_records.py", line 27, in <module>
    from kafka.record.legacy_records import LegacyRecordBatch, LegacyRecordBatchBuilder
  File "/home/airflow/.local/lib/python3.12/site-packages/kafka/record/legacy_records.py", line 50, in <module>
    from kafka.codec import (
  File "/home/airflow/.local/lib/python3.12/site-packages/kafka/codec.py", line 9, in <module>
    from kafka.vendor.six.moves import range
ModuleNotFoundError: No module named 'kafka.vendor.six.moves'
[2024-11-07T00:03:26.250+0000] {processor.py:842} WARNING - No viable dags retrieved from /opt/airflow/dags/airbyte_sync_fluxos.py
[2024-11-07T00:03:26.276+0000] {processor.py:183} INFO - Processing /opt/airflow/dags/airbyte_sync_fluxos.py took 0.105 seconds
[2024-11-07T00:03:56.757+0000] {processor.py:161} INFO - Started process (PID=8489) to work on /opt/airflow/dags/airbyte_sync_fluxos.py
[2024-11-07T00:03:56.759+0000] {processor.py:830} INFO - Processing file /opt/airflow/dags/airbyte_sync_fluxos.py for tasks to queue
[2024-11-07T00:03:56.762+0000] {logging_mixin.py:188} INFO - [2024-11-07T00:03:56.762+0000] {dagbag.py:545} INFO - Filling up the DagBag from /opt/airflow/dags/airbyte_sync_fluxos.py
[2024-11-07T00:03:56.839+0000] {logging_mixin.py:188} INFO - [2024-11-07T00:03:56.829+0000] {dagbag.py:355} ERROR - Failed to import: /opt/airflow/dags/airbyte_sync_fluxos.py
Traceback (most recent call last):
  File "/home/airflow/.local/lib/python3.12/site-packages/airflow/models/dagbag.py", line 351, in parse
    loader.exec_module(new_module)
  File "<frozen importlib._bootstrap_external>", line 995, in exec_module
  File "<frozen importlib._bootstrap>", line 488, in _call_with_frames_removed
  File "/opt/airflow/dags/airbyte_sync_fluxos.py", line 11, in <module>
    from kafka import KafkaConsumer
  File "/home/airflow/.local/lib/python3.12/site-packages/kafka/__init__.py", line 23, in <module>
    from kafka.consumer import KafkaConsumer
  File "/home/airflow/.local/lib/python3.12/site-packages/kafka/consumer/__init__.py", line 3, in <module>
    from kafka.consumer.group import KafkaConsumer
  File "/home/airflow/.local/lib/python3.12/site-packages/kafka/consumer/group.py", line 13, in <module>
    from kafka.consumer.fetcher import Fetcher
  File "/home/airflow/.local/lib/python3.12/site-packages/kafka/consumer/fetcher.py", line 19, in <module>
    from kafka.record import MemoryRecords
  File "/home/airflow/.local/lib/python3.12/site-packages/kafka/record/__init__.py", line 1, in <module>
    from kafka.record.memory_records import MemoryRecords, MemoryRecordsBuilder
  File "/home/airflow/.local/lib/python3.12/site-packages/kafka/record/memory_records.py", line 27, in <module>
    from kafka.record.legacy_records import LegacyRecordBatch, LegacyRecordBatchBuilder
  File "/home/airflow/.local/lib/python3.12/site-packages/kafka/record/legacy_records.py", line 50, in <module>
    from kafka.codec import (
  File "/home/airflow/.local/lib/python3.12/site-packages/kafka/codec.py", line 9, in <module>
    from kafka.vendor.six.moves import range
ModuleNotFoundError: No module named 'kafka.vendor.six.moves'
[2024-11-07T00:03:56.841+0000] {processor.py:842} WARNING - No viable dags retrieved from /opt/airflow/dags/airbyte_sync_fluxos.py
[2024-11-07T00:03:56.867+0000] {processor.py:183} INFO - Processing /opt/airflow/dags/airbyte_sync_fluxos.py took 0.116 seconds
[2024-11-07T00:04:27.326+0000] {processor.py:161} INFO - Started process (PID=8512) to work on /opt/airflow/dags/airbyte_sync_fluxos.py
[2024-11-07T00:04:27.327+0000] {processor.py:830} INFO - Processing file /opt/airflow/dags/airbyte_sync_fluxos.py for tasks to queue
[2024-11-07T00:04:27.330+0000] {logging_mixin.py:188} INFO - [2024-11-07T00:04:27.329+0000] {dagbag.py:545} INFO - Filling up the DagBag from /opt/airflow/dags/airbyte_sync_fluxos.py
[2024-11-07T00:04:27.398+0000] {logging_mixin.py:188} INFO - [2024-11-07T00:04:27.390+0000] {dagbag.py:355} ERROR - Failed to import: /opt/airflow/dags/airbyte_sync_fluxos.py
Traceback (most recent call last):
  File "/home/airflow/.local/lib/python3.12/site-packages/airflow/models/dagbag.py", line 351, in parse
    loader.exec_module(new_module)
  File "<frozen importlib._bootstrap_external>", line 995, in exec_module
  File "<frozen importlib._bootstrap>", line 488, in _call_with_frames_removed
  File "/opt/airflow/dags/airbyte_sync_fluxos.py", line 11, in <module>
    from kafka import KafkaConsumer
  File "/home/airflow/.local/lib/python3.12/site-packages/kafka/__init__.py", line 23, in <module>
    from kafka.consumer import KafkaConsumer
  File "/home/airflow/.local/lib/python3.12/site-packages/kafka/consumer/__init__.py", line 3, in <module>
    from kafka.consumer.group import KafkaConsumer
  File "/home/airflow/.local/lib/python3.12/site-packages/kafka/consumer/group.py", line 13, in <module>
    from kafka.consumer.fetcher import Fetcher
  File "/home/airflow/.local/lib/python3.12/site-packages/kafka/consumer/fetcher.py", line 19, in <module>
    from kafka.record import MemoryRecords
  File "/home/airflow/.local/lib/python3.12/site-packages/kafka/record/__init__.py", line 1, in <module>
    from kafka.record.memory_records import MemoryRecords, MemoryRecordsBuilder
  File "/home/airflow/.local/lib/python3.12/site-packages/kafka/record/memory_records.py", line 27, in <module>
    from kafka.record.legacy_records import LegacyRecordBatch, LegacyRecordBatchBuilder
  File "/home/airflow/.local/lib/python3.12/site-packages/kafka/record/legacy_records.py", line 50, in <module>
    from kafka.codec import (
  File "/home/airflow/.local/lib/python3.12/site-packages/kafka/codec.py", line 9, in <module>
    from kafka.vendor.six.moves import range
ModuleNotFoundError: No module named 'kafka.vendor.six.moves'
[2024-11-07T00:04:27.399+0000] {processor.py:842} WARNING - No viable dags retrieved from /opt/airflow/dags/airbyte_sync_fluxos.py
[2024-11-07T00:04:27.424+0000] {processor.py:183} INFO - Processing /opt/airflow/dags/airbyte_sync_fluxos.py took 0.105 seconds
[2024-11-07T00:04:58.068+0000] {processor.py:161} INFO - Started process (PID=8534) to work on /opt/airflow/dags/airbyte_sync_fluxos.py
[2024-11-07T00:04:58.070+0000] {processor.py:830} INFO - Processing file /opt/airflow/dags/airbyte_sync_fluxos.py for tasks to queue
[2024-11-07T00:04:58.078+0000] {logging_mixin.py:188} INFO - [2024-11-07T00:04:58.077+0000] {dagbag.py:545} INFO - Filling up the DagBag from /opt/airflow/dags/airbyte_sync_fluxos.py
[2024-11-07T00:04:58.286+0000] {logging_mixin.py:188} INFO - [2024-11-07T00:04:58.271+0000] {dagbag.py:355} ERROR - Failed to import: /opt/airflow/dags/airbyte_sync_fluxos.py
Traceback (most recent call last):
  File "/home/airflow/.local/lib/python3.12/site-packages/airflow/models/dagbag.py", line 351, in parse
    loader.exec_module(new_module)
  File "<frozen importlib._bootstrap_external>", line 995, in exec_module
  File "<frozen importlib._bootstrap>", line 488, in _call_with_frames_removed
  File "/opt/airflow/dags/airbyte_sync_fluxos.py", line 11, in <module>
    from kafka import KafkaConsumer
  File "/home/airflow/.local/lib/python3.12/site-packages/kafka/__init__.py", line 23, in <module>
    from kafka.consumer import KafkaConsumer
  File "/home/airflow/.local/lib/python3.12/site-packages/kafka/consumer/__init__.py", line 3, in <module>
    from kafka.consumer.group import KafkaConsumer
  File "/home/airflow/.local/lib/python3.12/site-packages/kafka/consumer/group.py", line 13, in <module>
    from kafka.consumer.fetcher import Fetcher
  File "/home/airflow/.local/lib/python3.12/site-packages/kafka/consumer/fetcher.py", line 19, in <module>
    from kafka.record import MemoryRecords
  File "/home/airflow/.local/lib/python3.12/site-packages/kafka/record/__init__.py", line 1, in <module>
    from kafka.record.memory_records import MemoryRecords, MemoryRecordsBuilder
  File "/home/airflow/.local/lib/python3.12/site-packages/kafka/record/memory_records.py", line 27, in <module>
    from kafka.record.legacy_records import LegacyRecordBatch, LegacyRecordBatchBuilder
  File "/home/airflow/.local/lib/python3.12/site-packages/kafka/record/legacy_records.py", line 50, in <module>
    from kafka.codec import (
  File "/home/airflow/.local/lib/python3.12/site-packages/kafka/codec.py", line 9, in <module>
    from kafka.vendor.six.moves import range
ModuleNotFoundError: No module named 'kafka.vendor.six.moves'
[2024-11-07T00:04:58.290+0000] {processor.py:842} WARNING - No viable dags retrieved from /opt/airflow/dags/airbyte_sync_fluxos.py
[2024-11-07T00:04:58.360+0000] {processor.py:183} INFO - Processing /opt/airflow/dags/airbyte_sync_fluxos.py took 0.309 seconds
[2024-11-07T00:05:28.688+0000] {processor.py:161} INFO - Started process (PID=8556) to work on /opt/airflow/dags/airbyte_sync_fluxos.py
[2024-11-07T00:05:28.690+0000] {processor.py:830} INFO - Processing file /opt/airflow/dags/airbyte_sync_fluxos.py for tasks to queue
[2024-11-07T00:05:28.692+0000] {logging_mixin.py:188} INFO - [2024-11-07T00:05:28.692+0000] {dagbag.py:545} INFO - Filling up the DagBag from /opt/airflow/dags/airbyte_sync_fluxos.py
[2024-11-07T00:05:28.767+0000] {logging_mixin.py:188} INFO - [2024-11-07T00:05:28.757+0000] {dagbag.py:355} ERROR - Failed to import: /opt/airflow/dags/airbyte_sync_fluxos.py
Traceback (most recent call last):
  File "/home/airflow/.local/lib/python3.12/site-packages/airflow/models/dagbag.py", line 351, in parse
    loader.exec_module(new_module)
  File "<frozen importlib._bootstrap_external>", line 995, in exec_module
  File "<frozen importlib._bootstrap>", line 488, in _call_with_frames_removed
  File "/opt/airflow/dags/airbyte_sync_fluxos.py", line 11, in <module>
    from kafka import KafkaConsumer
  File "/home/airflow/.local/lib/python3.12/site-packages/kafka/__init__.py", line 23, in <module>
    from kafka.consumer import KafkaConsumer
  File "/home/airflow/.local/lib/python3.12/site-packages/kafka/consumer/__init__.py", line 3, in <module>
    from kafka.consumer.group import KafkaConsumer
  File "/home/airflow/.local/lib/python3.12/site-packages/kafka/consumer/group.py", line 13, in <module>
    from kafka.consumer.fetcher import Fetcher
  File "/home/airflow/.local/lib/python3.12/site-packages/kafka/consumer/fetcher.py", line 19, in <module>
    from kafka.record import MemoryRecords
  File "/home/airflow/.local/lib/python3.12/site-packages/kafka/record/__init__.py", line 1, in <module>
    from kafka.record.memory_records import MemoryRecords, MemoryRecordsBuilder
  File "/home/airflow/.local/lib/python3.12/site-packages/kafka/record/memory_records.py", line 27, in <module>
    from kafka.record.legacy_records import LegacyRecordBatch, LegacyRecordBatchBuilder
  File "/home/airflow/.local/lib/python3.12/site-packages/kafka/record/legacy_records.py", line 50, in <module>
    from kafka.codec import (
  File "/home/airflow/.local/lib/python3.12/site-packages/kafka/codec.py", line 9, in <module>
    from kafka.vendor.six.moves import range
ModuleNotFoundError: No module named 'kafka.vendor.six.moves'
[2024-11-07T00:05:28.769+0000] {processor.py:842} WARNING - No viable dags retrieved from /opt/airflow/dags/airbyte_sync_fluxos.py
[2024-11-07T00:05:28.794+0000] {processor.py:183} INFO - Processing /opt/airflow/dags/airbyte_sync_fluxos.py took 0.112 seconds
[2024-11-07T00:05:59.290+0000] {processor.py:161} INFO - Started process (PID=8578) to work on /opt/airflow/dags/airbyte_sync_fluxos.py
[2024-11-07T00:05:59.292+0000] {processor.py:830} INFO - Processing file /opt/airflow/dags/airbyte_sync_fluxos.py for tasks to queue
[2024-11-07T00:05:59.294+0000] {logging_mixin.py:188} INFO - [2024-11-07T00:05:59.294+0000] {dagbag.py:545} INFO - Filling up the DagBag from /opt/airflow/dags/airbyte_sync_fluxos.py
[2024-11-07T00:05:59.385+0000] {logging_mixin.py:188} INFO - [2024-11-07T00:05:59.372+0000] {dagbag.py:355} ERROR - Failed to import: /opt/airflow/dags/airbyte_sync_fluxos.py
Traceback (most recent call last):
  File "/home/airflow/.local/lib/python3.12/site-packages/airflow/models/dagbag.py", line 351, in parse
    loader.exec_module(new_module)
  File "<frozen importlib._bootstrap_external>", line 995, in exec_module
  File "<frozen importlib._bootstrap>", line 488, in _call_with_frames_removed
  File "/opt/airflow/dags/airbyte_sync_fluxos.py", line 11, in <module>
    from kafka import KafkaConsumer
  File "/home/airflow/.local/lib/python3.12/site-packages/kafka/__init__.py", line 23, in <module>
    from kafka.consumer import KafkaConsumer
  File "/home/airflow/.local/lib/python3.12/site-packages/kafka/consumer/__init__.py", line 3, in <module>
    from kafka.consumer.group import KafkaConsumer
  File "/home/airflow/.local/lib/python3.12/site-packages/kafka/consumer/group.py", line 13, in <module>
    from kafka.consumer.fetcher import Fetcher
  File "/home/airflow/.local/lib/python3.12/site-packages/kafka/consumer/fetcher.py", line 19, in <module>
    from kafka.record import MemoryRecords
  File "/home/airflow/.local/lib/python3.12/site-packages/kafka/record/__init__.py", line 1, in <module>
    from kafka.record.memory_records import MemoryRecords, MemoryRecordsBuilder
  File "/home/airflow/.local/lib/python3.12/site-packages/kafka/record/memory_records.py", line 27, in <module>
    from kafka.record.legacy_records import LegacyRecordBatch, LegacyRecordBatchBuilder
  File "/home/airflow/.local/lib/python3.12/site-packages/kafka/record/legacy_records.py", line 50, in <module>
    from kafka.codec import (
  File "/home/airflow/.local/lib/python3.12/site-packages/kafka/codec.py", line 9, in <module>
    from kafka.vendor.six.moves import range
ModuleNotFoundError: No module named 'kafka.vendor.six.moves'
[2024-11-07T00:05:59.398+0000] {processor.py:842} WARNING - No viable dags retrieved from /opt/airflow/dags/airbyte_sync_fluxos.py
[2024-11-07T00:05:59.435+0000] {processor.py:183} INFO - Processing /opt/airflow/dags/airbyte_sync_fluxos.py took 0.151 seconds
[2024-11-07T00:06:29.867+0000] {processor.py:161} INFO - Started process (PID=8600) to work on /opt/airflow/dags/airbyte_sync_fluxos.py
[2024-11-07T00:06:29.869+0000] {processor.py:830} INFO - Processing file /opt/airflow/dags/airbyte_sync_fluxos.py for tasks to queue
[2024-11-07T00:06:29.872+0000] {logging_mixin.py:188} INFO - [2024-11-07T00:06:29.872+0000] {dagbag.py:545} INFO - Filling up the DagBag from /opt/airflow/dags/airbyte_sync_fluxos.py
[2024-11-07T00:06:29.963+0000] {logging_mixin.py:188} INFO - [2024-11-07T00:06:29.951+0000] {dagbag.py:355} ERROR - Failed to import: /opt/airflow/dags/airbyte_sync_fluxos.py
Traceback (most recent call last):
  File "/home/airflow/.local/lib/python3.12/site-packages/airflow/models/dagbag.py", line 351, in parse
    loader.exec_module(new_module)
  File "<frozen importlib._bootstrap_external>", line 995, in exec_module
  File "<frozen importlib._bootstrap>", line 488, in _call_with_frames_removed
  File "/opt/airflow/dags/airbyte_sync_fluxos.py", line 11, in <module>
    from kafka import KafkaConsumer
  File "/home/airflow/.local/lib/python3.12/site-packages/kafka/__init__.py", line 23, in <module>
    from kafka.consumer import KafkaConsumer
  File "/home/airflow/.local/lib/python3.12/site-packages/kafka/consumer/__init__.py", line 3, in <module>
    from kafka.consumer.group import KafkaConsumer
  File "/home/airflow/.local/lib/python3.12/site-packages/kafka/consumer/group.py", line 13, in <module>
    from kafka.consumer.fetcher import Fetcher
  File "/home/airflow/.local/lib/python3.12/site-packages/kafka/consumer/fetcher.py", line 19, in <module>
    from kafka.record import MemoryRecords
  File "/home/airflow/.local/lib/python3.12/site-packages/kafka/record/__init__.py", line 1, in <module>
    from kafka.record.memory_records import MemoryRecords, MemoryRecordsBuilder
  File "/home/airflow/.local/lib/python3.12/site-packages/kafka/record/memory_records.py", line 27, in <module>
    from kafka.record.legacy_records import LegacyRecordBatch, LegacyRecordBatchBuilder
  File "/home/airflow/.local/lib/python3.12/site-packages/kafka/record/legacy_records.py", line 50, in <module>
    from kafka.codec import (
  File "/home/airflow/.local/lib/python3.12/site-packages/kafka/codec.py", line 9, in <module>
    from kafka.vendor.six.moves import range
ModuleNotFoundError: No module named 'kafka.vendor.six.moves'
[2024-11-07T00:06:29.964+0000] {processor.py:842} WARNING - No viable dags retrieved from /opt/airflow/dags/airbyte_sync_fluxos.py
[2024-11-07T00:06:29.992+0000] {processor.py:183} INFO - Processing /opt/airflow/dags/airbyte_sync_fluxos.py took 0.130 seconds
[2024-11-07T00:07:00.318+0000] {processor.py:161} INFO - Started process (PID=8622) to work on /opt/airflow/dags/airbyte_sync_fluxos.py
[2024-11-07T00:07:00.324+0000] {processor.py:830} INFO - Processing file /opt/airflow/dags/airbyte_sync_fluxos.py for tasks to queue
[2024-11-07T00:07:00.332+0000] {logging_mixin.py:188} INFO - [2024-11-07T00:07:00.330+0000] {dagbag.py:545} INFO - Filling up the DagBag from /opt/airflow/dags/airbyte_sync_fluxos.py
[2024-11-07T00:07:00.670+0000] {logging_mixin.py:188} INFO - [2024-11-07T00:07:00.645+0000] {dagbag.py:355} ERROR - Failed to import: /opt/airflow/dags/airbyte_sync_fluxos.py
Traceback (most recent call last):
  File "/home/airflow/.local/lib/python3.12/site-packages/airflow/models/dagbag.py", line 351, in parse
    loader.exec_module(new_module)
  File "<frozen importlib._bootstrap_external>", line 995, in exec_module
  File "<frozen importlib._bootstrap>", line 488, in _call_with_frames_removed
  File "/opt/airflow/dags/airbyte_sync_fluxos.py", line 11, in <module>
    from kafka import KafkaConsumer
  File "/home/airflow/.local/lib/python3.12/site-packages/kafka/__init__.py", line 23, in <module>
    from kafka.consumer import KafkaConsumer
  File "/home/airflow/.local/lib/python3.12/site-packages/kafka/consumer/__init__.py", line 3, in <module>
    from kafka.consumer.group import KafkaConsumer
  File "/home/airflow/.local/lib/python3.12/site-packages/kafka/consumer/group.py", line 13, in <module>
    from kafka.consumer.fetcher import Fetcher
  File "/home/airflow/.local/lib/python3.12/site-packages/kafka/consumer/fetcher.py", line 19, in <module>
    from kafka.record import MemoryRecords
  File "/home/airflow/.local/lib/python3.12/site-packages/kafka/record/__init__.py", line 1, in <module>
    from kafka.record.memory_records import MemoryRecords, MemoryRecordsBuilder
  File "/home/airflow/.local/lib/python3.12/site-packages/kafka/record/memory_records.py", line 27, in <module>
    from kafka.record.legacy_records import LegacyRecordBatch, LegacyRecordBatchBuilder
  File "/home/airflow/.local/lib/python3.12/site-packages/kafka/record/legacy_records.py", line 50, in <module>
    from kafka.codec import (
  File "/home/airflow/.local/lib/python3.12/site-packages/kafka/codec.py", line 9, in <module>
    from kafka.vendor.six.moves import range
ModuleNotFoundError: No module named 'kafka.vendor.six.moves'
[2024-11-07T00:07:00.675+0000] {processor.py:842} WARNING - No viable dags retrieved from /opt/airflow/dags/airbyte_sync_fluxos.py
[2024-11-07T00:07:00.731+0000] {processor.py:183} INFO - Processing /opt/airflow/dags/airbyte_sync_fluxos.py took 0.457 seconds
[2024-11-07T00:07:31.146+0000] {processor.py:161} INFO - Started process (PID=8644) to work on /opt/airflow/dags/airbyte_sync_fluxos.py
[2024-11-07T00:07:31.152+0000] {processor.py:830} INFO - Processing file /opt/airflow/dags/airbyte_sync_fluxos.py for tasks to queue
[2024-11-07T00:07:31.156+0000] {logging_mixin.py:188} INFO - [2024-11-07T00:07:31.156+0000] {dagbag.py:545} INFO - Filling up the DagBag from /opt/airflow/dags/airbyte_sync_fluxos.py
[2024-11-07T00:07:31.311+0000] {logging_mixin.py:188} INFO - [2024-11-07T00:07:31.279+0000] {dagbag.py:355} ERROR - Failed to import: /opt/airflow/dags/airbyte_sync_fluxos.py
Traceback (most recent call last):
  File "/home/airflow/.local/lib/python3.12/site-packages/airflow/models/dagbag.py", line 351, in parse
    loader.exec_module(new_module)
  File "<frozen importlib._bootstrap_external>", line 995, in exec_module
  File "<frozen importlib._bootstrap>", line 488, in _call_with_frames_removed
  File "/opt/airflow/dags/airbyte_sync_fluxos.py", line 11, in <module>
    from kafka import KafkaConsumer
  File "/home/airflow/.local/lib/python3.12/site-packages/kafka/__init__.py", line 23, in <module>
    from kafka.consumer import KafkaConsumer
  File "/home/airflow/.local/lib/python3.12/site-packages/kafka/consumer/__init__.py", line 3, in <module>
    from kafka.consumer.group import KafkaConsumer
  File "/home/airflow/.local/lib/python3.12/site-packages/kafka/consumer/group.py", line 13, in <module>
    from kafka.consumer.fetcher import Fetcher
  File "/home/airflow/.local/lib/python3.12/site-packages/kafka/consumer/fetcher.py", line 19, in <module>
    from kafka.record import MemoryRecords
  File "/home/airflow/.local/lib/python3.12/site-packages/kafka/record/__init__.py", line 1, in <module>
    from kafka.record.memory_records import MemoryRecords, MemoryRecordsBuilder
  File "/home/airflow/.local/lib/python3.12/site-packages/kafka/record/memory_records.py", line 27, in <module>
    from kafka.record.legacy_records import LegacyRecordBatch, LegacyRecordBatchBuilder
  File "/home/airflow/.local/lib/python3.12/site-packages/kafka/record/legacy_records.py", line 50, in <module>
    from kafka.codec import (
  File "/home/airflow/.local/lib/python3.12/site-packages/kafka/codec.py", line 9, in <module>
    from kafka.vendor.six.moves import range
ModuleNotFoundError: No module named 'kafka.vendor.six.moves'
[2024-11-07T00:07:31.313+0000] {processor.py:842} WARNING - No viable dags retrieved from /opt/airflow/dags/airbyte_sync_fluxos.py
[2024-11-07T00:07:31.384+0000] {processor.py:183} INFO - Processing /opt/airflow/dags/airbyte_sync_fluxos.py took 0.264 seconds
[2024-11-07T00:08:02.083+0000] {processor.py:161} INFO - Started process (PID=8666) to work on /opt/airflow/dags/airbyte_sync_fluxos.py
[2024-11-07T00:08:02.086+0000] {processor.py:830} INFO - Processing file /opt/airflow/dags/airbyte_sync_fluxos.py for tasks to queue
[2024-11-07T00:08:02.092+0000] {logging_mixin.py:188} INFO - [2024-11-07T00:08:02.091+0000] {dagbag.py:545} INFO - Filling up the DagBag from /opt/airflow/dags/airbyte_sync_fluxos.py
[2024-11-07T00:08:02.276+0000] {logging_mixin.py:188} INFO - [2024-11-07T00:08:02.258+0000] {dagbag.py:355} ERROR - Failed to import: /opt/airflow/dags/airbyte_sync_fluxos.py
Traceback (most recent call last):
  File "/home/airflow/.local/lib/python3.12/site-packages/airflow/models/dagbag.py", line 351, in parse
    loader.exec_module(new_module)
  File "<frozen importlib._bootstrap_external>", line 995, in exec_module
  File "<frozen importlib._bootstrap>", line 488, in _call_with_frames_removed
  File "/opt/airflow/dags/airbyte_sync_fluxos.py", line 11, in <module>
    from kafka import KafkaConsumer
  File "/home/airflow/.local/lib/python3.12/site-packages/kafka/__init__.py", line 23, in <module>
    from kafka.consumer import KafkaConsumer
  File "/home/airflow/.local/lib/python3.12/site-packages/kafka/consumer/__init__.py", line 3, in <module>
    from kafka.consumer.group import KafkaConsumer
  File "/home/airflow/.local/lib/python3.12/site-packages/kafka/consumer/group.py", line 13, in <module>
    from kafka.consumer.fetcher import Fetcher
  File "/home/airflow/.local/lib/python3.12/site-packages/kafka/consumer/fetcher.py", line 19, in <module>
    from kafka.record import MemoryRecords
  File "/home/airflow/.local/lib/python3.12/site-packages/kafka/record/__init__.py", line 1, in <module>
    from kafka.record.memory_records import MemoryRecords, MemoryRecordsBuilder
  File "/home/airflow/.local/lib/python3.12/site-packages/kafka/record/memory_records.py", line 27, in <module>
    from kafka.record.legacy_records import LegacyRecordBatch, LegacyRecordBatchBuilder
  File "/home/airflow/.local/lib/python3.12/site-packages/kafka/record/legacy_records.py", line 50, in <module>
    from kafka.codec import (
  File "/home/airflow/.local/lib/python3.12/site-packages/kafka/codec.py", line 9, in <module>
    from kafka.vendor.six.moves import range
ModuleNotFoundError: No module named 'kafka.vendor.six.moves'
[2024-11-07T00:08:02.279+0000] {processor.py:842} WARNING - No viable dags retrieved from /opt/airflow/dags/airbyte_sync_fluxos.py
[2024-11-07T00:08:02.328+0000] {processor.py:183} INFO - Processing /opt/airflow/dags/airbyte_sync_fluxos.py took 0.271 seconds
[2024-11-07T00:08:33.005+0000] {processor.py:161} INFO - Started process (PID=8688) to work on /opt/airflow/dags/airbyte_sync_fluxos.py
[2024-11-07T00:08:33.007+0000] {processor.py:830} INFO - Processing file /opt/airflow/dags/airbyte_sync_fluxos.py for tasks to queue
[2024-11-07T00:08:33.010+0000] {logging_mixin.py:188} INFO - [2024-11-07T00:08:33.010+0000] {dagbag.py:545} INFO - Filling up the DagBag from /opt/airflow/dags/airbyte_sync_fluxos.py
[2024-11-07T00:08:33.103+0000] {logging_mixin.py:188} INFO - [2024-11-07T00:08:33.091+0000] {dagbag.py:355} ERROR - Failed to import: /opt/airflow/dags/airbyte_sync_fluxos.py
Traceback (most recent call last):
  File "/home/airflow/.local/lib/python3.12/site-packages/airflow/models/dagbag.py", line 351, in parse
    loader.exec_module(new_module)
  File "<frozen importlib._bootstrap_external>", line 995, in exec_module
  File "<frozen importlib._bootstrap>", line 488, in _call_with_frames_removed
  File "/opt/airflow/dags/airbyte_sync_fluxos.py", line 11, in <module>
    from kafka import KafkaConsumer
  File "/home/airflow/.local/lib/python3.12/site-packages/kafka/__init__.py", line 23, in <module>
    from kafka.consumer import KafkaConsumer
  File "/home/airflow/.local/lib/python3.12/site-packages/kafka/consumer/__init__.py", line 3, in <module>
    from kafka.consumer.group import KafkaConsumer
  File "/home/airflow/.local/lib/python3.12/site-packages/kafka/consumer/group.py", line 13, in <module>
    from kafka.consumer.fetcher import Fetcher
  File "/home/airflow/.local/lib/python3.12/site-packages/kafka/consumer/fetcher.py", line 19, in <module>
    from kafka.record import MemoryRecords
  File "/home/airflow/.local/lib/python3.12/site-packages/kafka/record/__init__.py", line 1, in <module>
    from kafka.record.memory_records import MemoryRecords, MemoryRecordsBuilder
  File "/home/airflow/.local/lib/python3.12/site-packages/kafka/record/memory_records.py", line 27, in <module>
    from kafka.record.legacy_records import LegacyRecordBatch, LegacyRecordBatchBuilder
  File "/home/airflow/.local/lib/python3.12/site-packages/kafka/record/legacy_records.py", line 50, in <module>
    from kafka.codec import (
  File "/home/airflow/.local/lib/python3.12/site-packages/kafka/codec.py", line 9, in <module>
    from kafka.vendor.six.moves import range
ModuleNotFoundError: No module named 'kafka.vendor.six.moves'
[2024-11-07T00:08:33.105+0000] {processor.py:842} WARNING - No viable dags retrieved from /opt/airflow/dags/airbyte_sync_fluxos.py
[2024-11-07T00:08:33.139+0000] {processor.py:183} INFO - Processing /opt/airflow/dags/airbyte_sync_fluxos.py took 0.140 seconds
[2024-11-07T00:09:04.267+0000] {processor.py:161} INFO - Started process (PID=8710) to work on /opt/airflow/dags/airbyte_sync_fluxos.py
[2024-11-07T00:09:04.275+0000] {processor.py:830} INFO - Processing file /opt/airflow/dags/airbyte_sync_fluxos.py for tasks to queue
[2024-11-07T00:09:04.286+0000] {logging_mixin.py:188} INFO - [2024-11-07T00:09:04.285+0000] {dagbag.py:545} INFO - Filling up the DagBag from /opt/airflow/dags/airbyte_sync_fluxos.py
[2024-11-07T00:09:04.554+0000] {logging_mixin.py:188} INFO - [2024-11-07T00:09:04.524+0000] {dagbag.py:355} ERROR - Failed to import: /opt/airflow/dags/airbyte_sync_fluxos.py
Traceback (most recent call last):
  File "/home/airflow/.local/lib/python3.12/site-packages/airflow/models/dagbag.py", line 351, in parse
    loader.exec_module(new_module)
  File "<frozen importlib._bootstrap_external>", line 995, in exec_module
  File "<frozen importlib._bootstrap>", line 488, in _call_with_frames_removed
  File "/opt/airflow/dags/airbyte_sync_fluxos.py", line 11, in <module>
    from kafka import KafkaConsumer
  File "/home/airflow/.local/lib/python3.12/site-packages/kafka/__init__.py", line 23, in <module>
    from kafka.consumer import KafkaConsumer
  File "/home/airflow/.local/lib/python3.12/site-packages/kafka/consumer/__init__.py", line 3, in <module>
    from kafka.consumer.group import KafkaConsumer
  File "/home/airflow/.local/lib/python3.12/site-packages/kafka/consumer/group.py", line 13, in <module>
    from kafka.consumer.fetcher import Fetcher
  File "/home/airflow/.local/lib/python3.12/site-packages/kafka/consumer/fetcher.py", line 19, in <module>
    from kafka.record import MemoryRecords
  File "/home/airflow/.local/lib/python3.12/site-packages/kafka/record/__init__.py", line 1, in <module>
    from kafka.record.memory_records import MemoryRecords, MemoryRecordsBuilder
  File "/home/airflow/.local/lib/python3.12/site-packages/kafka/record/memory_records.py", line 27, in <module>
    from kafka.record.legacy_records import LegacyRecordBatch, LegacyRecordBatchBuilder
  File "/home/airflow/.local/lib/python3.12/site-packages/kafka/record/legacy_records.py", line 50, in <module>
    from kafka.codec import (
  File "/home/airflow/.local/lib/python3.12/site-packages/kafka/codec.py", line 9, in <module>
    from kafka.vendor.six.moves import range
ModuleNotFoundError: No module named 'kafka.vendor.six.moves'
[2024-11-07T00:09:04.557+0000] {processor.py:842} WARNING - No viable dags retrieved from /opt/airflow/dags/airbyte_sync_fluxos.py
[2024-11-07T00:09:04.626+0000] {processor.py:183} INFO - Processing /opt/airflow/dags/airbyte_sync_fluxos.py took 0.388 seconds
[2024-11-07T00:09:35.631+0000] {processor.py:161} INFO - Started process (PID=8732) to work on /opt/airflow/dags/airbyte_sync_fluxos.py
[2024-11-07T00:09:35.644+0000] {processor.py:830} INFO - Processing file /opt/airflow/dags/airbyte_sync_fluxos.py for tasks to queue
[2024-11-07T00:09:35.655+0000] {logging_mixin.py:188} INFO - [2024-11-07T00:09:35.653+0000] {dagbag.py:545} INFO - Filling up the DagBag from /opt/airflow/dags/airbyte_sync_fluxos.py
[2024-11-07T00:09:36.370+0000] {logging_mixin.py:188} INFO - [2024-11-07T00:09:36.245+0000] {dagbag.py:355} ERROR - Failed to import: /opt/airflow/dags/airbyte_sync_fluxos.py
Traceback (most recent call last):
  File "/home/airflow/.local/lib/python3.12/site-packages/airflow/models/dagbag.py", line 351, in parse
    loader.exec_module(new_module)
  File "<frozen importlib._bootstrap_external>", line 995, in exec_module
  File "<frozen importlib._bootstrap>", line 488, in _call_with_frames_removed
  File "/opt/airflow/dags/airbyte_sync_fluxos.py", line 11, in <module>
    from kafka import KafkaConsumer
  File "/home/airflow/.local/lib/python3.12/site-packages/kafka/__init__.py", line 23, in <module>
    from kafka.consumer import KafkaConsumer
  File "/home/airflow/.local/lib/python3.12/site-packages/kafka/consumer/__init__.py", line 3, in <module>
    from kafka.consumer.group import KafkaConsumer
  File "/home/airflow/.local/lib/python3.12/site-packages/kafka/consumer/group.py", line 13, in <module>
    from kafka.consumer.fetcher import Fetcher
  File "/home/airflow/.local/lib/python3.12/site-packages/kafka/consumer/fetcher.py", line 19, in <module>
    from kafka.record import MemoryRecords
  File "/home/airflow/.local/lib/python3.12/site-packages/kafka/record/__init__.py", line 1, in <module>
    from kafka.record.memory_records import MemoryRecords, MemoryRecordsBuilder
  File "/home/airflow/.local/lib/python3.12/site-packages/kafka/record/memory_records.py", line 27, in <module>
    from kafka.record.legacy_records import LegacyRecordBatch, LegacyRecordBatchBuilder
  File "/home/airflow/.local/lib/python3.12/site-packages/kafka/record/legacy_records.py", line 50, in <module>
    from kafka.codec import (
  File "/home/airflow/.local/lib/python3.12/site-packages/kafka/codec.py", line 9, in <module>
    from kafka.vendor.six.moves import range
ModuleNotFoundError: No module named 'kafka.vendor.six.moves'
[2024-11-07T00:09:36.378+0000] {processor.py:842} WARNING - No viable dags retrieved from /opt/airflow/dags/airbyte_sync_fluxos.py
[2024-11-07T00:09:36.600+0000] {processor.py:183} INFO - Processing /opt/airflow/dags/airbyte_sync_fluxos.py took 1.022 seconds
[2024-11-07T00:10:06.830+0000] {processor.py:161} INFO - Started process (PID=8754) to work on /opt/airflow/dags/airbyte_sync_fluxos.py
[2024-11-07T00:10:06.832+0000] {processor.py:830} INFO - Processing file /opt/airflow/dags/airbyte_sync_fluxos.py for tasks to queue
[2024-11-07T00:10:06.835+0000] {logging_mixin.py:188} INFO - [2024-11-07T00:10:06.834+0000] {dagbag.py:545} INFO - Filling up the DagBag from /opt/airflow/dags/airbyte_sync_fluxos.py
[2024-11-07T00:10:06.928+0000] {logging_mixin.py:188} INFO - [2024-11-07T00:10:06.916+0000] {dagbag.py:355} ERROR - Failed to import: /opt/airflow/dags/airbyte_sync_fluxos.py
Traceback (most recent call last):
  File "/home/airflow/.local/lib/python3.12/site-packages/airflow/models/dagbag.py", line 351, in parse
    loader.exec_module(new_module)
  File "<frozen importlib._bootstrap_external>", line 995, in exec_module
  File "<frozen importlib._bootstrap>", line 488, in _call_with_frames_removed
  File "/opt/airflow/dags/airbyte_sync_fluxos.py", line 11, in <module>
    from kafka import KafkaConsumer
  File "/home/airflow/.local/lib/python3.12/site-packages/kafka/__init__.py", line 23, in <module>
    from kafka.consumer import KafkaConsumer
  File "/home/airflow/.local/lib/python3.12/site-packages/kafka/consumer/__init__.py", line 3, in <module>
    from kafka.consumer.group import KafkaConsumer
  File "/home/airflow/.local/lib/python3.12/site-packages/kafka/consumer/group.py", line 13, in <module>
    from kafka.consumer.fetcher import Fetcher
  File "/home/airflow/.local/lib/python3.12/site-packages/kafka/consumer/fetcher.py", line 19, in <module>
    from kafka.record import MemoryRecords
  File "/home/airflow/.local/lib/python3.12/site-packages/kafka/record/__init__.py", line 1, in <module>
    from kafka.record.memory_records import MemoryRecords, MemoryRecordsBuilder
  File "/home/airflow/.local/lib/python3.12/site-packages/kafka/record/memory_records.py", line 27, in <module>
    from kafka.record.legacy_records import LegacyRecordBatch, LegacyRecordBatchBuilder
  File "/home/airflow/.local/lib/python3.12/site-packages/kafka/record/legacy_records.py", line 50, in <module>
    from kafka.codec import (
  File "/home/airflow/.local/lib/python3.12/site-packages/kafka/codec.py", line 9, in <module>
    from kafka.vendor.six.moves import range
ModuleNotFoundError: No module named 'kafka.vendor.six.moves'
[2024-11-07T00:10:06.930+0000] {processor.py:842} WARNING - No viable dags retrieved from /opt/airflow/dags/airbyte_sync_fluxos.py
[2024-11-07T00:10:06.974+0000] {processor.py:183} INFO - Processing /opt/airflow/dags/airbyte_sync_fluxos.py took 0.153 seconds
[2024-11-07T00:10:37.380+0000] {processor.py:161} INFO - Started process (PID=8776) to work on /opt/airflow/dags/airbyte_sync_fluxos.py
[2024-11-07T00:10:37.382+0000] {processor.py:830} INFO - Processing file /opt/airflow/dags/airbyte_sync_fluxos.py for tasks to queue
[2024-11-07T00:10:37.388+0000] {logging_mixin.py:188} INFO - [2024-11-07T00:10:37.387+0000] {dagbag.py:545} INFO - Filling up the DagBag from /opt/airflow/dags/airbyte_sync_fluxos.py
[2024-11-07T00:10:37.512+0000] {logging_mixin.py:188} INFO - [2024-11-07T00:10:37.499+0000] {dagbag.py:355} ERROR - Failed to import: /opt/airflow/dags/airbyte_sync_fluxos.py
Traceback (most recent call last):
  File "/home/airflow/.local/lib/python3.12/site-packages/airflow/models/dagbag.py", line 351, in parse
    loader.exec_module(new_module)
  File "<frozen importlib._bootstrap_external>", line 995, in exec_module
  File "<frozen importlib._bootstrap>", line 488, in _call_with_frames_removed
  File "/opt/airflow/dags/airbyte_sync_fluxos.py", line 11, in <module>
    from kafka import KafkaConsumer
  File "/home/airflow/.local/lib/python3.12/site-packages/kafka/__init__.py", line 23, in <module>
    from kafka.consumer import KafkaConsumer
  File "/home/airflow/.local/lib/python3.12/site-packages/kafka/consumer/__init__.py", line 3, in <module>
    from kafka.consumer.group import KafkaConsumer
  File "/home/airflow/.local/lib/python3.12/site-packages/kafka/consumer/group.py", line 13, in <module>
    from kafka.consumer.fetcher import Fetcher
  File "/home/airflow/.local/lib/python3.12/site-packages/kafka/consumer/fetcher.py", line 19, in <module>
    from kafka.record import MemoryRecords
  File "/home/airflow/.local/lib/python3.12/site-packages/kafka/record/__init__.py", line 1, in <module>
    from kafka.record.memory_records import MemoryRecords, MemoryRecordsBuilder
  File "/home/airflow/.local/lib/python3.12/site-packages/kafka/record/memory_records.py", line 27, in <module>
    from kafka.record.legacy_records import LegacyRecordBatch, LegacyRecordBatchBuilder
  File "/home/airflow/.local/lib/python3.12/site-packages/kafka/record/legacy_records.py", line 50, in <module>
    from kafka.codec import (
  File "/home/airflow/.local/lib/python3.12/site-packages/kafka/codec.py", line 9, in <module>
    from kafka.vendor.six.moves import range
ModuleNotFoundError: No module named 'kafka.vendor.six.moves'
[2024-11-07T00:10:37.514+0000] {processor.py:842} WARNING - No viable dags retrieved from /opt/airflow/dags/airbyte_sync_fluxos.py
[2024-11-07T00:10:37.557+0000] {processor.py:183} INFO - Processing /opt/airflow/dags/airbyte_sync_fluxos.py took 0.192 seconds
[2024-11-07T00:11:07.824+0000] {processor.py:161} INFO - Started process (PID=8798) to work on /opt/airflow/dags/airbyte_sync_fluxos.py
[2024-11-07T00:11:07.835+0000] {processor.py:830} INFO - Processing file /opt/airflow/dags/airbyte_sync_fluxos.py for tasks to queue
[2024-11-07T00:11:07.843+0000] {logging_mixin.py:188} INFO - [2024-11-07T00:11:07.842+0000] {dagbag.py:545} INFO - Filling up the DagBag from /opt/airflow/dags/airbyte_sync_fluxos.py
[2024-11-07T00:11:08.179+0000] {logging_mixin.py:188} INFO - [2024-11-07T00:11:08.151+0000] {dagbag.py:355} ERROR - Failed to import: /opt/airflow/dags/airbyte_sync_fluxos.py
Traceback (most recent call last):
  File "/home/airflow/.local/lib/python3.12/site-packages/airflow/models/dagbag.py", line 351, in parse
    loader.exec_module(new_module)
  File "<frozen importlib._bootstrap_external>", line 995, in exec_module
  File "<frozen importlib._bootstrap>", line 488, in _call_with_frames_removed
  File "/opt/airflow/dags/airbyte_sync_fluxos.py", line 11, in <module>
    from kafka import KafkaConsumer
  File "/home/airflow/.local/lib/python3.12/site-packages/kafka/__init__.py", line 23, in <module>
    from kafka.consumer import KafkaConsumer
  File "/home/airflow/.local/lib/python3.12/site-packages/kafka/consumer/__init__.py", line 3, in <module>
    from kafka.consumer.group import KafkaConsumer
  File "/home/airflow/.local/lib/python3.12/site-packages/kafka/consumer/group.py", line 13, in <module>
    from kafka.consumer.fetcher import Fetcher
  File "/home/airflow/.local/lib/python3.12/site-packages/kafka/consumer/fetcher.py", line 19, in <module>
    from kafka.record import MemoryRecords
  File "/home/airflow/.local/lib/python3.12/site-packages/kafka/record/__init__.py", line 1, in <module>
    from kafka.record.memory_records import MemoryRecords, MemoryRecordsBuilder
  File "/home/airflow/.local/lib/python3.12/site-packages/kafka/record/memory_records.py", line 27, in <module>
    from kafka.record.legacy_records import LegacyRecordBatch, LegacyRecordBatchBuilder
  File "/home/airflow/.local/lib/python3.12/site-packages/kafka/record/legacy_records.py", line 50, in <module>
    from kafka.codec import (
  File "/home/airflow/.local/lib/python3.12/site-packages/kafka/codec.py", line 9, in <module>
    from kafka.vendor.six.moves import range
ModuleNotFoundError: No module named 'kafka.vendor.six.moves'
[2024-11-07T00:11:08.181+0000] {processor.py:842} WARNING - No viable dags retrieved from /opt/airflow/dags/airbyte_sync_fluxos.py
[2024-11-07T00:11:08.311+0000] {processor.py:183} INFO - Processing /opt/airflow/dags/airbyte_sync_fluxos.py took 0.520 seconds
[2024-11-07T00:11:38.934+0000] {processor.py:161} INFO - Started process (PID=8820) to work on /opt/airflow/dags/airbyte_sync_fluxos.py
[2024-11-07T00:11:38.936+0000] {processor.py:830} INFO - Processing file /opt/airflow/dags/airbyte_sync_fluxos.py for tasks to queue
[2024-11-07T00:11:38.938+0000] {logging_mixin.py:188} INFO - [2024-11-07T00:11:38.937+0000] {dagbag.py:545} INFO - Filling up the DagBag from /opt/airflow/dags/airbyte_sync_fluxos.py
[2024-11-07T00:11:39.020+0000] {logging_mixin.py:188} INFO - [2024-11-07T00:11:39.013+0000] {dagbag.py:355} ERROR - Failed to import: /opt/airflow/dags/airbyte_sync_fluxos.py
Traceback (most recent call last):
  File "/home/airflow/.local/lib/python3.12/site-packages/airflow/models/dagbag.py", line 351, in parse
    loader.exec_module(new_module)
  File "<frozen importlib._bootstrap_external>", line 995, in exec_module
  File "<frozen importlib._bootstrap>", line 488, in _call_with_frames_removed
  File "/opt/airflow/dags/airbyte_sync_fluxos.py", line 11, in <module>
    from kafka import KafkaConsumer
  File "/home/airflow/.local/lib/python3.12/site-packages/kafka/__init__.py", line 23, in <module>
    from kafka.consumer import KafkaConsumer
  File "/home/airflow/.local/lib/python3.12/site-packages/kafka/consumer/__init__.py", line 3, in <module>
    from kafka.consumer.group import KafkaConsumer
  File "/home/airflow/.local/lib/python3.12/site-packages/kafka/consumer/group.py", line 13, in <module>
    from kafka.consumer.fetcher import Fetcher
  File "/home/airflow/.local/lib/python3.12/site-packages/kafka/consumer/fetcher.py", line 19, in <module>
    from kafka.record import MemoryRecords
  File "/home/airflow/.local/lib/python3.12/site-packages/kafka/record/__init__.py", line 1, in <module>
    from kafka.record.memory_records import MemoryRecords, MemoryRecordsBuilder
  File "/home/airflow/.local/lib/python3.12/site-packages/kafka/record/memory_records.py", line 27, in <module>
    from kafka.record.legacy_records import LegacyRecordBatch, LegacyRecordBatchBuilder
  File "/home/airflow/.local/lib/python3.12/site-packages/kafka/record/legacy_records.py", line 50, in <module>
    from kafka.codec import (
  File "/home/airflow/.local/lib/python3.12/site-packages/kafka/codec.py", line 9, in <module>
    from kafka.vendor.six.moves import range
ModuleNotFoundError: No module named 'kafka.vendor.six.moves'
[2024-11-07T00:11:39.022+0000] {processor.py:842} WARNING - No viable dags retrieved from /opt/airflow/dags/airbyte_sync_fluxos.py
[2024-11-07T00:11:39.049+0000] {processor.py:183} INFO - Processing /opt/airflow/dags/airbyte_sync_fluxos.py took 0.122 seconds
[2024-11-07T00:12:09.652+0000] {processor.py:161} INFO - Started process (PID=8842) to work on /opt/airflow/dags/airbyte_sync_fluxos.py
[2024-11-07T00:12:09.654+0000] {processor.py:830} INFO - Processing file /opt/airflow/dags/airbyte_sync_fluxos.py for tasks to queue
[2024-11-07T00:12:09.656+0000] {logging_mixin.py:188} INFO - [2024-11-07T00:12:09.656+0000] {dagbag.py:545} INFO - Filling up the DagBag from /opt/airflow/dags/airbyte_sync_fluxos.py
[2024-11-07T00:12:09.738+0000] {logging_mixin.py:188} INFO - [2024-11-07T00:12:09.732+0000] {dagbag.py:355} ERROR - Failed to import: /opt/airflow/dags/airbyte_sync_fluxos.py
Traceback (most recent call last):
  File "/home/airflow/.local/lib/python3.12/site-packages/airflow/models/dagbag.py", line 351, in parse
    loader.exec_module(new_module)
  File "<frozen importlib._bootstrap_external>", line 995, in exec_module
  File "<frozen importlib._bootstrap>", line 488, in _call_with_frames_removed
  File "/opt/airflow/dags/airbyte_sync_fluxos.py", line 11, in <module>
    from kafka import KafkaConsumer
  File "/home/airflow/.local/lib/python3.12/site-packages/kafka/__init__.py", line 23, in <module>
    from kafka.consumer import KafkaConsumer
  File "/home/airflow/.local/lib/python3.12/site-packages/kafka/consumer/__init__.py", line 3, in <module>
    from kafka.consumer.group import KafkaConsumer
  File "/home/airflow/.local/lib/python3.12/site-packages/kafka/consumer/group.py", line 13, in <module>
    from kafka.consumer.fetcher import Fetcher
  File "/home/airflow/.local/lib/python3.12/site-packages/kafka/consumer/fetcher.py", line 19, in <module>
    from kafka.record import MemoryRecords
  File "/home/airflow/.local/lib/python3.12/site-packages/kafka/record/__init__.py", line 1, in <module>
    from kafka.record.memory_records import MemoryRecords, MemoryRecordsBuilder
  File "/home/airflow/.local/lib/python3.12/site-packages/kafka/record/memory_records.py", line 27, in <module>
    from kafka.record.legacy_records import LegacyRecordBatch, LegacyRecordBatchBuilder
  File "/home/airflow/.local/lib/python3.12/site-packages/kafka/record/legacy_records.py", line 50, in <module>
    from kafka.codec import (
  File "/home/airflow/.local/lib/python3.12/site-packages/kafka/codec.py", line 9, in <module>
    from kafka.vendor.six.moves import range
ModuleNotFoundError: No module named 'kafka.vendor.six.moves'
[2024-11-07T00:12:09.740+0000] {processor.py:842} WARNING - No viable dags retrieved from /opt/airflow/dags/airbyte_sync_fluxos.py
[2024-11-07T00:12:09.777+0000] {processor.py:183} INFO - Processing /opt/airflow/dags/airbyte_sync_fluxos.py took 0.135 seconds
[2024-11-07T00:12:40.341+0000] {processor.py:161} INFO - Started process (PID=8864) to work on /opt/airflow/dags/airbyte_sync_fluxos.py
[2024-11-07T00:12:40.344+0000] {processor.py:830} INFO - Processing file /opt/airflow/dags/airbyte_sync_fluxos.py for tasks to queue
[2024-11-07T00:12:40.348+0000] {logging_mixin.py:188} INFO - [2024-11-07T00:12:40.347+0000] {dagbag.py:545} INFO - Filling up the DagBag from /opt/airflow/dags/airbyte_sync_fluxos.py
[2024-11-07T00:12:40.426+0000] {logging_mixin.py:188} INFO - [2024-11-07T00:12:40.417+0000] {dagbag.py:355} ERROR - Failed to import: /opt/airflow/dags/airbyte_sync_fluxos.py
Traceback (most recent call last):
  File "/home/airflow/.local/lib/python3.12/site-packages/airflow/models/dagbag.py", line 351, in parse
    loader.exec_module(new_module)
  File "<frozen importlib._bootstrap_external>", line 995, in exec_module
  File "<frozen importlib._bootstrap>", line 488, in _call_with_frames_removed
  File "/opt/airflow/dags/airbyte_sync_fluxos.py", line 11, in <module>
    from kafka import KafkaConsumer
  File "/home/airflow/.local/lib/python3.12/site-packages/kafka/__init__.py", line 23, in <module>
    from kafka.consumer import KafkaConsumer
  File "/home/airflow/.local/lib/python3.12/site-packages/kafka/consumer/__init__.py", line 3, in <module>
    from kafka.consumer.group import KafkaConsumer
  File "/home/airflow/.local/lib/python3.12/site-packages/kafka/consumer/group.py", line 13, in <module>
    from kafka.consumer.fetcher import Fetcher
  File "/home/airflow/.local/lib/python3.12/site-packages/kafka/consumer/fetcher.py", line 19, in <module>
    from kafka.record import MemoryRecords
  File "/home/airflow/.local/lib/python3.12/site-packages/kafka/record/__init__.py", line 1, in <module>
    from kafka.record.memory_records import MemoryRecords, MemoryRecordsBuilder
  File "/home/airflow/.local/lib/python3.12/site-packages/kafka/record/memory_records.py", line 27, in <module>
    from kafka.record.legacy_records import LegacyRecordBatch, LegacyRecordBatchBuilder
  File "/home/airflow/.local/lib/python3.12/site-packages/kafka/record/legacy_records.py", line 50, in <module>
    from kafka.codec import (
  File "/home/airflow/.local/lib/python3.12/site-packages/kafka/codec.py", line 9, in <module>
    from kafka.vendor.six.moves import range
ModuleNotFoundError: No module named 'kafka.vendor.six.moves'
[2024-11-07T00:12:40.428+0000] {processor.py:842} WARNING - No viable dags retrieved from /opt/airflow/dags/airbyte_sync_fluxos.py
[2024-11-07T00:12:40.458+0000] {processor.py:183} INFO - Processing /opt/airflow/dags/airbyte_sync_fluxos.py took 0.125 seconds
[2024-11-07T00:13:10.895+0000] {processor.py:161} INFO - Started process (PID=8887) to work on /opt/airflow/dags/airbyte_sync_fluxos.py
[2024-11-07T00:13:10.897+0000] {processor.py:830} INFO - Processing file /opt/airflow/dags/airbyte_sync_fluxos.py for tasks to queue
[2024-11-07T00:13:10.900+0000] {logging_mixin.py:188} INFO - [2024-11-07T00:13:10.900+0000] {dagbag.py:545} INFO - Filling up the DagBag from /opt/airflow/dags/airbyte_sync_fluxos.py
[2024-11-07T00:13:10.989+0000] {logging_mixin.py:188} INFO - [2024-11-07T00:13:10.981+0000] {dagbag.py:355} ERROR - Failed to import: /opt/airflow/dags/airbyte_sync_fluxos.py
Traceback (most recent call last):
  File "/home/airflow/.local/lib/python3.12/site-packages/airflow/models/dagbag.py", line 351, in parse
    loader.exec_module(new_module)
  File "<frozen importlib._bootstrap_external>", line 995, in exec_module
  File "<frozen importlib._bootstrap>", line 488, in _call_with_frames_removed
  File "/opt/airflow/dags/airbyte_sync_fluxos.py", line 11, in <module>
    from kafka import KafkaConsumer
  File "/home/airflow/.local/lib/python3.12/site-packages/kafka/__init__.py", line 23, in <module>
    from kafka.consumer import KafkaConsumer
  File "/home/airflow/.local/lib/python3.12/site-packages/kafka/consumer/__init__.py", line 3, in <module>
    from kafka.consumer.group import KafkaConsumer
  File "/home/airflow/.local/lib/python3.12/site-packages/kafka/consumer/group.py", line 13, in <module>
    from kafka.consumer.fetcher import Fetcher
  File "/home/airflow/.local/lib/python3.12/site-packages/kafka/consumer/fetcher.py", line 19, in <module>
    from kafka.record import MemoryRecords
  File "/home/airflow/.local/lib/python3.12/site-packages/kafka/record/__init__.py", line 1, in <module>
    from kafka.record.memory_records import MemoryRecords, MemoryRecordsBuilder
  File "/home/airflow/.local/lib/python3.12/site-packages/kafka/record/memory_records.py", line 27, in <module>
    from kafka.record.legacy_records import LegacyRecordBatch, LegacyRecordBatchBuilder
  File "/home/airflow/.local/lib/python3.12/site-packages/kafka/record/legacy_records.py", line 50, in <module>
    from kafka.codec import (
  File "/home/airflow/.local/lib/python3.12/site-packages/kafka/codec.py", line 9, in <module>
    from kafka.vendor.six.moves import range
ModuleNotFoundError: No module named 'kafka.vendor.six.moves'
[2024-11-07T00:13:10.991+0000] {processor.py:842} WARNING - No viable dags retrieved from /opt/airflow/dags/airbyte_sync_fluxos.py
[2024-11-07T00:13:11.024+0000] {processor.py:183} INFO - Processing /opt/airflow/dags/airbyte_sync_fluxos.py took 0.139 seconds
[2024-11-07T00:13:41.506+0000] {processor.py:161} INFO - Started process (PID=8909) to work on /opt/airflow/dags/airbyte_sync_fluxos.py
[2024-11-07T00:13:41.508+0000] {processor.py:830} INFO - Processing file /opt/airflow/dags/airbyte_sync_fluxos.py for tasks to queue
[2024-11-07T00:13:41.513+0000] {logging_mixin.py:188} INFO - [2024-11-07T00:13:41.512+0000] {dagbag.py:545} INFO - Filling up the DagBag from /opt/airflow/dags/airbyte_sync_fluxos.py
[2024-11-07T00:13:41.597+0000] {logging_mixin.py:188} INFO - [2024-11-07T00:13:41.588+0000] {dagbag.py:355} ERROR - Failed to import: /opt/airflow/dags/airbyte_sync_fluxos.py
Traceback (most recent call last):
  File "/home/airflow/.local/lib/python3.12/site-packages/airflow/models/dagbag.py", line 351, in parse
    loader.exec_module(new_module)
  File "<frozen importlib._bootstrap_external>", line 995, in exec_module
  File "<frozen importlib._bootstrap>", line 488, in _call_with_frames_removed
  File "/opt/airflow/dags/airbyte_sync_fluxos.py", line 11, in <module>
    from kafka import KafkaConsumer
  File "/home/airflow/.local/lib/python3.12/site-packages/kafka/__init__.py", line 23, in <module>
    from kafka.consumer import KafkaConsumer
  File "/home/airflow/.local/lib/python3.12/site-packages/kafka/consumer/__init__.py", line 3, in <module>
    from kafka.consumer.group import KafkaConsumer
  File "/home/airflow/.local/lib/python3.12/site-packages/kafka/consumer/group.py", line 13, in <module>
    from kafka.consumer.fetcher import Fetcher
  File "/home/airflow/.local/lib/python3.12/site-packages/kafka/consumer/fetcher.py", line 19, in <module>
    from kafka.record import MemoryRecords
  File "/home/airflow/.local/lib/python3.12/site-packages/kafka/record/__init__.py", line 1, in <module>
    from kafka.record.memory_records import MemoryRecords, MemoryRecordsBuilder
  File "/home/airflow/.local/lib/python3.12/site-packages/kafka/record/memory_records.py", line 27, in <module>
    from kafka.record.legacy_records import LegacyRecordBatch, LegacyRecordBatchBuilder
  File "/home/airflow/.local/lib/python3.12/site-packages/kafka/record/legacy_records.py", line 50, in <module>
    from kafka.codec import (
  File "/home/airflow/.local/lib/python3.12/site-packages/kafka/codec.py", line 9, in <module>
    from kafka.vendor.six.moves import range
ModuleNotFoundError: No module named 'kafka.vendor.six.moves'
[2024-11-07T00:13:41.598+0000] {processor.py:842} WARNING - No viable dags retrieved from /opt/airflow/dags/airbyte_sync_fluxos.py
[2024-11-07T00:13:41.625+0000] {processor.py:183} INFO - Processing /opt/airflow/dags/airbyte_sync_fluxos.py took 0.127 seconds
[2024-11-07T00:14:12.122+0000] {processor.py:161} INFO - Started process (PID=8931) to work on /opt/airflow/dags/airbyte_sync_fluxos.py
[2024-11-07T00:14:12.124+0000] {processor.py:830} INFO - Processing file /opt/airflow/dags/airbyte_sync_fluxos.py for tasks to queue
[2024-11-07T00:14:12.127+0000] {logging_mixin.py:188} INFO - [2024-11-07T00:14:12.127+0000] {dagbag.py:545} INFO - Filling up the DagBag from /opt/airflow/dags/airbyte_sync_fluxos.py
[2024-11-07T00:14:12.212+0000] {logging_mixin.py:188} INFO - [2024-11-07T00:14:12.201+0000] {dagbag.py:355} ERROR - Failed to import: /opt/airflow/dags/airbyte_sync_fluxos.py
Traceback (most recent call last):
  File "/home/airflow/.local/lib/python3.12/site-packages/airflow/models/dagbag.py", line 351, in parse
    loader.exec_module(new_module)
  File "<frozen importlib._bootstrap_external>", line 995, in exec_module
  File "<frozen importlib._bootstrap>", line 488, in _call_with_frames_removed
  File "/opt/airflow/dags/airbyte_sync_fluxos.py", line 11, in <module>
    from kafka import KafkaConsumer
  File "/home/airflow/.local/lib/python3.12/site-packages/kafka/__init__.py", line 23, in <module>
    from kafka.consumer import KafkaConsumer
  File "/home/airflow/.local/lib/python3.12/site-packages/kafka/consumer/__init__.py", line 3, in <module>
    from kafka.consumer.group import KafkaConsumer
  File "/home/airflow/.local/lib/python3.12/site-packages/kafka/consumer/group.py", line 13, in <module>
    from kafka.consumer.fetcher import Fetcher
  File "/home/airflow/.local/lib/python3.12/site-packages/kafka/consumer/fetcher.py", line 19, in <module>
    from kafka.record import MemoryRecords
  File "/home/airflow/.local/lib/python3.12/site-packages/kafka/record/__init__.py", line 1, in <module>
    from kafka.record.memory_records import MemoryRecords, MemoryRecordsBuilder
  File "/home/airflow/.local/lib/python3.12/site-packages/kafka/record/memory_records.py", line 27, in <module>
    from kafka.record.legacy_records import LegacyRecordBatch, LegacyRecordBatchBuilder
  File "/home/airflow/.local/lib/python3.12/site-packages/kafka/record/legacy_records.py", line 50, in <module>
    from kafka.codec import (
  File "/home/airflow/.local/lib/python3.12/site-packages/kafka/codec.py", line 9, in <module>
    from kafka.vendor.six.moves import range
ModuleNotFoundError: No module named 'kafka.vendor.six.moves'
[2024-11-07T00:14:12.214+0000] {processor.py:842} WARNING - No viable dags retrieved from /opt/airflow/dags/airbyte_sync_fluxos.py
[2024-11-07T00:14:12.251+0000] {processor.py:183} INFO - Processing /opt/airflow/dags/airbyte_sync_fluxos.py took 0.135 seconds
[2024-11-07T00:14:42.793+0000] {processor.py:161} INFO - Started process (PID=8953) to work on /opt/airflow/dags/airbyte_sync_fluxos.py
[2024-11-07T00:14:42.796+0000] {processor.py:830} INFO - Processing file /opt/airflow/dags/airbyte_sync_fluxos.py for tasks to queue
[2024-11-07T00:14:42.803+0000] {logging_mixin.py:188} INFO - [2024-11-07T00:14:42.802+0000] {dagbag.py:545} INFO - Filling up the DagBag from /opt/airflow/dags/airbyte_sync_fluxos.py
[2024-11-07T00:14:43.069+0000] {logging_mixin.py:188} INFO - [2024-11-07T00:14:43.048+0000] {dagbag.py:355} ERROR - Failed to import: /opt/airflow/dags/airbyte_sync_fluxos.py
Traceback (most recent call last):
  File "/home/airflow/.local/lib/python3.12/site-packages/airflow/models/dagbag.py", line 351, in parse
    loader.exec_module(new_module)
  File "<frozen importlib._bootstrap_external>", line 995, in exec_module
  File "<frozen importlib._bootstrap>", line 488, in _call_with_frames_removed
  File "/opt/airflow/dags/airbyte_sync_fluxos.py", line 11, in <module>
    from kafka import KafkaConsumer
  File "/home/airflow/.local/lib/python3.12/site-packages/kafka/__init__.py", line 23, in <module>
    from kafka.consumer import KafkaConsumer
  File "/home/airflow/.local/lib/python3.12/site-packages/kafka/consumer/__init__.py", line 3, in <module>
    from kafka.consumer.group import KafkaConsumer
  File "/home/airflow/.local/lib/python3.12/site-packages/kafka/consumer/group.py", line 13, in <module>
    from kafka.consumer.fetcher import Fetcher
  File "/home/airflow/.local/lib/python3.12/site-packages/kafka/consumer/fetcher.py", line 19, in <module>
    from kafka.record import MemoryRecords
  File "/home/airflow/.local/lib/python3.12/site-packages/kafka/record/__init__.py", line 1, in <module>
    from kafka.record.memory_records import MemoryRecords, MemoryRecordsBuilder
  File "/home/airflow/.local/lib/python3.12/site-packages/kafka/record/memory_records.py", line 27, in <module>
    from kafka.record.legacy_records import LegacyRecordBatch, LegacyRecordBatchBuilder
  File "/home/airflow/.local/lib/python3.12/site-packages/kafka/record/legacy_records.py", line 50, in <module>
    from kafka.codec import (
  File "/home/airflow/.local/lib/python3.12/site-packages/kafka/codec.py", line 9, in <module>
    from kafka.vendor.six.moves import range
ModuleNotFoundError: No module named 'kafka.vendor.six.moves'
[2024-11-07T00:14:43.073+0000] {processor.py:842} WARNING - No viable dags retrieved from /opt/airflow/dags/airbyte_sync_fluxos.py
[2024-11-07T00:14:43.150+0000] {processor.py:183} INFO - Processing /opt/airflow/dags/airbyte_sync_fluxos.py took 0.375 seconds
[2024-11-07T00:15:13.660+0000] {processor.py:161} INFO - Started process (PID=8975) to work on /opt/airflow/dags/airbyte_sync_fluxos.py
[2024-11-07T00:15:13.665+0000] {processor.py:830} INFO - Processing file /opt/airflow/dags/airbyte_sync_fluxos.py for tasks to queue
[2024-11-07T00:15:13.685+0000] {logging_mixin.py:188} INFO - [2024-11-07T00:15:13.683+0000] {dagbag.py:545} INFO - Filling up the DagBag from /opt/airflow/dags/airbyte_sync_fluxos.py
[2024-11-07T00:15:14.062+0000] {logging_mixin.py:188} INFO - [2024-11-07T00:15:14.015+0000] {dagbag.py:355} ERROR - Failed to import: /opt/airflow/dags/airbyte_sync_fluxos.py
Traceback (most recent call last):
  File "/home/airflow/.local/lib/python3.12/site-packages/airflow/models/dagbag.py", line 351, in parse
    loader.exec_module(new_module)
  File "<frozen importlib._bootstrap_external>", line 995, in exec_module
  File "<frozen importlib._bootstrap>", line 488, in _call_with_frames_removed
  File "/opt/airflow/dags/airbyte_sync_fluxos.py", line 11, in <module>
    from kafka import KafkaConsumer
  File "/home/airflow/.local/lib/python3.12/site-packages/kafka/__init__.py", line 23, in <module>
    from kafka.consumer import KafkaConsumer
  File "/home/airflow/.local/lib/python3.12/site-packages/kafka/consumer/__init__.py", line 3, in <module>
    from kafka.consumer.group import KafkaConsumer
  File "/home/airflow/.local/lib/python3.12/site-packages/kafka/consumer/group.py", line 13, in <module>
    from kafka.consumer.fetcher import Fetcher
  File "/home/airflow/.local/lib/python3.12/site-packages/kafka/consumer/fetcher.py", line 19, in <module>
    from kafka.record import MemoryRecords
  File "/home/airflow/.local/lib/python3.12/site-packages/kafka/record/__init__.py", line 1, in <module>
    from kafka.record.memory_records import MemoryRecords, MemoryRecordsBuilder
  File "/home/airflow/.local/lib/python3.12/site-packages/kafka/record/memory_records.py", line 27, in <module>
    from kafka.record.legacy_records import LegacyRecordBatch, LegacyRecordBatchBuilder
  File "/home/airflow/.local/lib/python3.12/site-packages/kafka/record/legacy_records.py", line 50, in <module>
    from kafka.codec import (
  File "/home/airflow/.local/lib/python3.12/site-packages/kafka/codec.py", line 9, in <module>
    from kafka.vendor.six.moves import range
ModuleNotFoundError: No module named 'kafka.vendor.six.moves'
[2024-11-07T00:15:14.070+0000] {processor.py:842} WARNING - No viable dags retrieved from /opt/airflow/dags/airbyte_sync_fluxos.py
[2024-11-07T00:15:14.220+0000] {processor.py:183} INFO - Processing /opt/airflow/dags/airbyte_sync_fluxos.py took 0.605 seconds
[2024-11-07T00:15:46.586+0000] {processor.py:161} INFO - Started process (PID=8996) to work on /opt/airflow/dags/airbyte_sync_fluxos.py
[2024-11-07T00:15:46.618+0000] {processor.py:830} INFO - Processing file /opt/airflow/dags/airbyte_sync_fluxos.py for tasks to queue
[2024-11-07T00:15:46.653+0000] {logging_mixin.py:188} INFO - [2024-11-07T00:15:46.651+0000] {dagbag.py:545} INFO - Filling up the DagBag from /opt/airflow/dags/airbyte_sync_fluxos.py
[2024-11-07T00:15:48.389+0000] {logging_mixin.py:188} INFO - [2024-11-07T00:15:48.253+0000] {dagbag.py:355} ERROR - Failed to import: /opt/airflow/dags/airbyte_sync_fluxos.py
Traceback (most recent call last):
  File "/home/airflow/.local/lib/python3.12/site-packages/airflow/models/dagbag.py", line 351, in parse
    loader.exec_module(new_module)
  File "<frozen importlib._bootstrap_external>", line 995, in exec_module
  File "<frozen importlib._bootstrap>", line 488, in _call_with_frames_removed
  File "/opt/airflow/dags/airbyte_sync_fluxos.py", line 11, in <module>
    from kafka import KafkaConsumer
  File "/home/airflow/.local/lib/python3.12/site-packages/kafka/__init__.py", line 23, in <module>
    from kafka.consumer import KafkaConsumer
  File "/home/airflow/.local/lib/python3.12/site-packages/kafka/consumer/__init__.py", line 3, in <module>
    from kafka.consumer.group import KafkaConsumer
  File "/home/airflow/.local/lib/python3.12/site-packages/kafka/consumer/group.py", line 13, in <module>
    from kafka.consumer.fetcher import Fetcher
  File "/home/airflow/.local/lib/python3.12/site-packages/kafka/consumer/fetcher.py", line 19, in <module>
    from kafka.record import MemoryRecords
  File "/home/airflow/.local/lib/python3.12/site-packages/kafka/record/__init__.py", line 1, in <module>
    from kafka.record.memory_records import MemoryRecords, MemoryRecordsBuilder
  File "/home/airflow/.local/lib/python3.12/site-packages/kafka/record/memory_records.py", line 27, in <module>
    from kafka.record.legacy_records import LegacyRecordBatch, LegacyRecordBatchBuilder
  File "/home/airflow/.local/lib/python3.12/site-packages/kafka/record/legacy_records.py", line 50, in <module>
    from kafka.codec import (
  File "/home/airflow/.local/lib/python3.12/site-packages/kafka/codec.py", line 9, in <module>
    from kafka.vendor.six.moves import range
ModuleNotFoundError: No module named 'kafka.vendor.six.moves'
[2024-11-07T00:15:48.404+0000] {processor.py:842} WARNING - No viable dags retrieved from /opt/airflow/dags/airbyte_sync_fluxos.py
[2024-11-07T00:15:48.766+0000] {processor.py:183} INFO - Processing /opt/airflow/dags/airbyte_sync_fluxos.py took 2.414 seconds
[2024-11-07T00:16:19.942+0000] {processor.py:161} INFO - Started process (PID=9018) to work on /opt/airflow/dags/airbyte_sync_fluxos.py
[2024-11-07T00:16:19.992+0000] {processor.py:830} INFO - Processing file /opt/airflow/dags/airbyte_sync_fluxos.py for tasks to queue
[2024-11-07T00:16:20.036+0000] {logging_mixin.py:188} INFO - [2024-11-07T00:16:20.035+0000] {dagbag.py:545} INFO - Filling up the DagBag from /opt/airflow/dags/airbyte_sync_fluxos.py
[2024-11-07T00:16:21.357+0000] {logging_mixin.py:188} INFO - [2024-11-07T00:16:21.260+0000] {dagbag.py:355} ERROR - Failed to import: /opt/airflow/dags/airbyte_sync_fluxos.py
Traceback (most recent call last):
  File "/home/airflow/.local/lib/python3.12/site-packages/airflow/models/dagbag.py", line 351, in parse
    loader.exec_module(new_module)
  File "<frozen importlib._bootstrap_external>", line 995, in exec_module
  File "<frozen importlib._bootstrap>", line 488, in _call_with_frames_removed
  File "/opt/airflow/dags/airbyte_sync_fluxos.py", line 11, in <module>
    from kafka import KafkaConsumer
  File "/home/airflow/.local/lib/python3.12/site-packages/kafka/__init__.py", line 23, in <module>
    from kafka.consumer import KafkaConsumer
  File "/home/airflow/.local/lib/python3.12/site-packages/kafka/consumer/__init__.py", line 3, in <module>
    from kafka.consumer.group import KafkaConsumer
  File "/home/airflow/.local/lib/python3.12/site-packages/kafka/consumer/group.py", line 13, in <module>
    from kafka.consumer.fetcher import Fetcher
  File "/home/airflow/.local/lib/python3.12/site-packages/kafka/consumer/fetcher.py", line 19, in <module>
    from kafka.record import MemoryRecords
  File "/home/airflow/.local/lib/python3.12/site-packages/kafka/record/__init__.py", line 1, in <module>
    from kafka.record.memory_records import MemoryRecords, MemoryRecordsBuilder
  File "/home/airflow/.local/lib/python3.12/site-packages/kafka/record/memory_records.py", line 27, in <module>
    from kafka.record.legacy_records import LegacyRecordBatch, LegacyRecordBatchBuilder
  File "/home/airflow/.local/lib/python3.12/site-packages/kafka/record/legacy_records.py", line 50, in <module>
    from kafka.codec import (
  File "/home/airflow/.local/lib/python3.12/site-packages/kafka/codec.py", line 9, in <module>
    from kafka.vendor.six.moves import range
ModuleNotFoundError: No module named 'kafka.vendor.six.moves'
[2024-11-07T00:16:21.405+0000] {processor.py:842} WARNING - No viable dags retrieved from /opt/airflow/dags/airbyte_sync_fluxos.py
[2024-11-07T00:16:21.843+0000] {processor.py:183} INFO - Processing /opt/airflow/dags/airbyte_sync_fluxos.py took 2.080 seconds
[2024-11-07T00:16:52.970+0000] {processor.py:161} INFO - Started process (PID=9040) to work on /opt/airflow/dags/airbyte_sync_fluxos.py
[2024-11-07T00:16:52.978+0000] {processor.py:830} INFO - Processing file /opt/airflow/dags/airbyte_sync_fluxos.py for tasks to queue
[2024-11-07T00:16:52.997+0000] {logging_mixin.py:188} INFO - [2024-11-07T00:16:52.994+0000] {dagbag.py:545} INFO - Filling up the DagBag from /opt/airflow/dags/airbyte_sync_fluxos.py
[2024-11-07T00:16:53.785+0000] {logging_mixin.py:188} INFO - [2024-11-07T00:16:53.731+0000] {dagbag.py:355} ERROR - Failed to import: /opt/airflow/dags/airbyte_sync_fluxos.py
Traceback (most recent call last):
  File "/home/airflow/.local/lib/python3.12/site-packages/airflow/models/dagbag.py", line 351, in parse
    loader.exec_module(new_module)
  File "<frozen importlib._bootstrap_external>", line 995, in exec_module
  File "<frozen importlib._bootstrap>", line 488, in _call_with_frames_removed
  File "/opt/airflow/dags/airbyte_sync_fluxos.py", line 11, in <module>
    from kafka import KafkaConsumer
  File "/home/airflow/.local/lib/python3.12/site-packages/kafka/__init__.py", line 23, in <module>
    from kafka.consumer import KafkaConsumer
  File "/home/airflow/.local/lib/python3.12/site-packages/kafka/consumer/__init__.py", line 3, in <module>
    from kafka.consumer.group import KafkaConsumer
  File "/home/airflow/.local/lib/python3.12/site-packages/kafka/consumer/group.py", line 13, in <module>
    from kafka.consumer.fetcher import Fetcher
  File "/home/airflow/.local/lib/python3.12/site-packages/kafka/consumer/fetcher.py", line 19, in <module>
    from kafka.record import MemoryRecords
  File "/home/airflow/.local/lib/python3.12/site-packages/kafka/record/__init__.py", line 1, in <module>
    from kafka.record.memory_records import MemoryRecords, MemoryRecordsBuilder
  File "/home/airflow/.local/lib/python3.12/site-packages/kafka/record/memory_records.py", line 27, in <module>
    from kafka.record.legacy_records import LegacyRecordBatch, LegacyRecordBatchBuilder
  File "/home/airflow/.local/lib/python3.12/site-packages/kafka/record/legacy_records.py", line 50, in <module>
    from kafka.codec import (
  File "/home/airflow/.local/lib/python3.12/site-packages/kafka/codec.py", line 9, in <module>
    from kafka.vendor.six.moves import range
ModuleNotFoundError: No module named 'kafka.vendor.six.moves'
[2024-11-07T00:16:53.794+0000] {processor.py:842} WARNING - No viable dags retrieved from /opt/airflow/dags/airbyte_sync_fluxos.py
[2024-11-07T00:16:54.029+0000] {processor.py:183} INFO - Processing /opt/airflow/dags/airbyte_sync_fluxos.py took 1.141 seconds
[2024-11-07T00:17:24.746+0000] {processor.py:161} INFO - Started process (PID=9063) to work on /opt/airflow/dags/airbyte_sync_fluxos.py
[2024-11-07T00:17:24.752+0000] {processor.py:830} INFO - Processing file /opt/airflow/dags/airbyte_sync_fluxos.py for tasks to queue
[2024-11-07T00:17:24.765+0000] {logging_mixin.py:188} INFO - [2024-11-07T00:17:24.763+0000] {dagbag.py:545} INFO - Filling up the DagBag from /opt/airflow/dags/airbyte_sync_fluxos.py
[2024-11-07T00:17:25.663+0000] {logging_mixin.py:188} INFO - [2024-11-07T00:17:25.357+0000] {dagbag.py:355} ERROR - Failed to import: /opt/airflow/dags/airbyte_sync_fluxos.py
Traceback (most recent call last):
  File "/home/airflow/.local/lib/python3.12/site-packages/airflow/models/dagbag.py", line 351, in parse
    loader.exec_module(new_module)
  File "<frozen importlib._bootstrap_external>", line 995, in exec_module
  File "<frozen importlib._bootstrap>", line 488, in _call_with_frames_removed
  File "/opt/airflow/dags/airbyte_sync_fluxos.py", line 11, in <module>
    from kafka import KafkaConsumer
  File "/home/airflow/.local/lib/python3.12/site-packages/kafka/__init__.py", line 23, in <module>
    from kafka.consumer import KafkaConsumer
  File "/home/airflow/.local/lib/python3.12/site-packages/kafka/consumer/__init__.py", line 3, in <module>
    from kafka.consumer.group import KafkaConsumer
  File "/home/airflow/.local/lib/python3.12/site-packages/kafka/consumer/group.py", line 13, in <module>
    from kafka.consumer.fetcher import Fetcher
  File "/home/airflow/.local/lib/python3.12/site-packages/kafka/consumer/fetcher.py", line 19, in <module>
    from kafka.record import MemoryRecords
  File "/home/airflow/.local/lib/python3.12/site-packages/kafka/record/__init__.py", line 1, in <module>
    from kafka.record.memory_records import MemoryRecords, MemoryRecordsBuilder
  File "/home/airflow/.local/lib/python3.12/site-packages/kafka/record/memory_records.py", line 27, in <module>
    from kafka.record.legacy_records import LegacyRecordBatch, LegacyRecordBatchBuilder
  File "/home/airflow/.local/lib/python3.12/site-packages/kafka/record/legacy_records.py", line 50, in <module>
    from kafka.codec import (
  File "/home/airflow/.local/lib/python3.12/site-packages/kafka/codec.py", line 9, in <module>
    from kafka.vendor.six.moves import range
ModuleNotFoundError: No module named 'kafka.vendor.six.moves'
[2024-11-07T00:17:25.674+0000] {processor.py:842} WARNING - No viable dags retrieved from /opt/airflow/dags/airbyte_sync_fluxos.py
[2024-11-07T00:17:26.148+0000] {processor.py:183} INFO - Processing /opt/airflow/dags/airbyte_sync_fluxos.py took 1.494 seconds
[2024-11-07T00:17:56.718+0000] {processor.py:161} INFO - Started process (PID=9085) to work on /opt/airflow/dags/airbyte_sync_fluxos.py
[2024-11-07T00:17:56.721+0000] {processor.py:830} INFO - Processing file /opt/airflow/dags/airbyte_sync_fluxos.py for tasks to queue
[2024-11-07T00:17:56.728+0000] {logging_mixin.py:188} INFO - [2024-11-07T00:17:56.727+0000] {dagbag.py:545} INFO - Filling up the DagBag from /opt/airflow/dags/airbyte_sync_fluxos.py
[2024-11-07T00:17:56.911+0000] {logging_mixin.py:188} INFO - [2024-11-07T00:17:56.896+0000] {dagbag.py:355} ERROR - Failed to import: /opt/airflow/dags/airbyte_sync_fluxos.py
Traceback (most recent call last):
  File "/home/airflow/.local/lib/python3.12/site-packages/airflow/models/dagbag.py", line 351, in parse
    loader.exec_module(new_module)
  File "<frozen importlib._bootstrap_external>", line 995, in exec_module
  File "<frozen importlib._bootstrap>", line 488, in _call_with_frames_removed
  File "/opt/airflow/dags/airbyte_sync_fluxos.py", line 11, in <module>
    from kafka import KafkaConsumer
  File "/home/airflow/.local/lib/python3.12/site-packages/kafka/__init__.py", line 23, in <module>
    from kafka.consumer import KafkaConsumer
  File "/home/airflow/.local/lib/python3.12/site-packages/kafka/consumer/__init__.py", line 3, in <module>
    from kafka.consumer.group import KafkaConsumer
  File "/home/airflow/.local/lib/python3.12/site-packages/kafka/consumer/group.py", line 13, in <module>
    from kafka.consumer.fetcher import Fetcher
  File "/home/airflow/.local/lib/python3.12/site-packages/kafka/consumer/fetcher.py", line 19, in <module>
    from kafka.record import MemoryRecords
  File "/home/airflow/.local/lib/python3.12/site-packages/kafka/record/__init__.py", line 1, in <module>
    from kafka.record.memory_records import MemoryRecords, MemoryRecordsBuilder
  File "/home/airflow/.local/lib/python3.12/site-packages/kafka/record/memory_records.py", line 27, in <module>
    from kafka.record.legacy_records import LegacyRecordBatch, LegacyRecordBatchBuilder
  File "/home/airflow/.local/lib/python3.12/site-packages/kafka/record/legacy_records.py", line 50, in <module>
    from kafka.codec import (
  File "/home/airflow/.local/lib/python3.12/site-packages/kafka/codec.py", line 9, in <module>
    from kafka.vendor.six.moves import range
ModuleNotFoundError: No module named 'kafka.vendor.six.moves'
[2024-11-07T00:17:56.913+0000] {processor.py:842} WARNING - No viable dags retrieved from /opt/airflow/dags/airbyte_sync_fluxos.py
[2024-11-07T00:17:56.962+0000] {processor.py:183} INFO - Processing /opt/airflow/dags/airbyte_sync_fluxos.py took 0.270 seconds
[2024-11-07T00:18:27.594+0000] {processor.py:161} INFO - Started process (PID=9110) to work on /opt/airflow/dags/airbyte_sync_fluxos.py
[2024-11-07T00:18:27.596+0000] {processor.py:830} INFO - Processing file /opt/airflow/dags/airbyte_sync_fluxos.py for tasks to queue
[2024-11-07T00:18:27.601+0000] {logging_mixin.py:188} INFO - [2024-11-07T00:18:27.600+0000] {dagbag.py:545} INFO - Filling up the DagBag from /opt/airflow/dags/airbyte_sync_fluxos.py
[2024-11-07T00:18:27.791+0000] {logging_mixin.py:188} INFO - [2024-11-07T00:18:27.780+0000] {dagbag.py:355} ERROR - Failed to import: /opt/airflow/dags/airbyte_sync_fluxos.py
Traceback (most recent call last):
  File "/home/airflow/.local/lib/python3.12/site-packages/airflow/models/dagbag.py", line 351, in parse
    loader.exec_module(new_module)
  File "<frozen importlib._bootstrap_external>", line 995, in exec_module
  File "<frozen importlib._bootstrap>", line 488, in _call_with_frames_removed
  File "/opt/airflow/dags/airbyte_sync_fluxos.py", line 11, in <module>
    from kafka import KafkaConsumer
  File "/home/airflow/.local/lib/python3.12/site-packages/kafka/__init__.py", line 23, in <module>
    from kafka.consumer import KafkaConsumer
  File "/home/airflow/.local/lib/python3.12/site-packages/kafka/consumer/__init__.py", line 3, in <module>
    from kafka.consumer.group import KafkaConsumer
  File "/home/airflow/.local/lib/python3.12/site-packages/kafka/consumer/group.py", line 13, in <module>
    from kafka.consumer.fetcher import Fetcher
  File "/home/airflow/.local/lib/python3.12/site-packages/kafka/consumer/fetcher.py", line 19, in <module>
    from kafka.record import MemoryRecords
  File "/home/airflow/.local/lib/python3.12/site-packages/kafka/record/__init__.py", line 1, in <module>
    from kafka.record.memory_records import MemoryRecords, MemoryRecordsBuilder
  File "/home/airflow/.local/lib/python3.12/site-packages/kafka/record/memory_records.py", line 27, in <module>
    from kafka.record.legacy_records import LegacyRecordBatch, LegacyRecordBatchBuilder
  File "/home/airflow/.local/lib/python3.12/site-packages/kafka/record/legacy_records.py", line 50, in <module>
    from kafka.codec import (
  File "/home/airflow/.local/lib/python3.12/site-packages/kafka/codec.py", line 9, in <module>
    from kafka.vendor.six.moves import range
ModuleNotFoundError: No module named 'kafka.vendor.six.moves'
[2024-11-07T00:18:27.813+0000] {processor.py:842} WARNING - No viable dags retrieved from /opt/airflow/dags/airbyte_sync_fluxos.py
[2024-11-07T00:18:27.840+0000] {processor.py:183} INFO - Processing /opt/airflow/dags/airbyte_sync_fluxos.py took 0.259 seconds
[2024-11-07T00:18:58.319+0000] {processor.py:161} INFO - Started process (PID=9133) to work on /opt/airflow/dags/airbyte_sync_fluxos.py
[2024-11-07T00:18:58.320+0000] {processor.py:830} INFO - Processing file /opt/airflow/dags/airbyte_sync_fluxos.py for tasks to queue
[2024-11-07T00:18:58.325+0000] {logging_mixin.py:188} INFO - [2024-11-07T00:18:58.324+0000] {dagbag.py:545} INFO - Filling up the DagBag from /opt/airflow/dags/airbyte_sync_fluxos.py
[2024-11-07T00:18:58.440+0000] {logging_mixin.py:188} INFO - [2024-11-07T00:18:58.428+0000] {dagbag.py:355} ERROR - Failed to import: /opt/airflow/dags/airbyte_sync_fluxos.py
Traceback (most recent call last):
  File "/home/airflow/.local/lib/python3.12/site-packages/airflow/models/dagbag.py", line 351, in parse
    loader.exec_module(new_module)
  File "<frozen importlib._bootstrap_external>", line 995, in exec_module
  File "<frozen importlib._bootstrap>", line 488, in _call_with_frames_removed
  File "/opt/airflow/dags/airbyte_sync_fluxos.py", line 11, in <module>
    from kafka import KafkaConsumer
  File "/home/airflow/.local/lib/python3.12/site-packages/kafka/__init__.py", line 23, in <module>
    from kafka.consumer import KafkaConsumer
  File "/home/airflow/.local/lib/python3.12/site-packages/kafka/consumer/__init__.py", line 3, in <module>
    from kafka.consumer.group import KafkaConsumer
  File "/home/airflow/.local/lib/python3.12/site-packages/kafka/consumer/group.py", line 13, in <module>
    from kafka.consumer.fetcher import Fetcher
  File "/home/airflow/.local/lib/python3.12/site-packages/kafka/consumer/fetcher.py", line 19, in <module>
    from kafka.record import MemoryRecords
  File "/home/airflow/.local/lib/python3.12/site-packages/kafka/record/__init__.py", line 1, in <module>
    from kafka.record.memory_records import MemoryRecords, MemoryRecordsBuilder
  File "/home/airflow/.local/lib/python3.12/site-packages/kafka/record/memory_records.py", line 27, in <module>
    from kafka.record.legacy_records import LegacyRecordBatch, LegacyRecordBatchBuilder
  File "/home/airflow/.local/lib/python3.12/site-packages/kafka/record/legacy_records.py", line 50, in <module>
    from kafka.codec import (
  File "/home/airflow/.local/lib/python3.12/site-packages/kafka/codec.py", line 9, in <module>
    from kafka.vendor.six.moves import range
ModuleNotFoundError: No module named 'kafka.vendor.six.moves'
[2024-11-07T00:18:58.442+0000] {processor.py:842} WARNING - No viable dags retrieved from /opt/airflow/dags/airbyte_sync_fluxos.py
[2024-11-07T00:18:58.510+0000] {processor.py:183} INFO - Processing /opt/airflow/dags/airbyte_sync_fluxos.py took 0.201 seconds
[2024-11-07T00:19:28.979+0000] {processor.py:161} INFO - Started process (PID=9155) to work on /opt/airflow/dags/airbyte_sync_fluxos.py
[2024-11-07T00:19:28.981+0000] {processor.py:830} INFO - Processing file /opt/airflow/dags/airbyte_sync_fluxos.py for tasks to queue
[2024-11-07T00:19:28.997+0000] {logging_mixin.py:188} INFO - [2024-11-07T00:19:28.997+0000] {dagbag.py:545} INFO - Filling up the DagBag from /opt/airflow/dags/airbyte_sync_fluxos.py
[2024-11-07T00:19:29.128+0000] {logging_mixin.py:188} INFO - [2024-11-07T00:19:29.118+0000] {dagbag.py:355} ERROR - Failed to import: /opt/airflow/dags/airbyte_sync_fluxos.py
Traceback (most recent call last):
  File "/home/airflow/.local/lib/python3.12/site-packages/airflow/models/dagbag.py", line 351, in parse
    loader.exec_module(new_module)
  File "<frozen importlib._bootstrap_external>", line 995, in exec_module
  File "<frozen importlib._bootstrap>", line 488, in _call_with_frames_removed
  File "/opt/airflow/dags/airbyte_sync_fluxos.py", line 11, in <module>
    from kafka import KafkaConsumer
  File "/home/airflow/.local/lib/python3.12/site-packages/kafka/__init__.py", line 23, in <module>
    from kafka.consumer import KafkaConsumer
  File "/home/airflow/.local/lib/python3.12/site-packages/kafka/consumer/__init__.py", line 3, in <module>
    from kafka.consumer.group import KafkaConsumer
  File "/home/airflow/.local/lib/python3.12/site-packages/kafka/consumer/group.py", line 13, in <module>
    from kafka.consumer.fetcher import Fetcher
  File "/home/airflow/.local/lib/python3.12/site-packages/kafka/consumer/fetcher.py", line 19, in <module>
    from kafka.record import MemoryRecords
  File "/home/airflow/.local/lib/python3.12/site-packages/kafka/record/__init__.py", line 1, in <module>
    from kafka.record.memory_records import MemoryRecords, MemoryRecordsBuilder
  File "/home/airflow/.local/lib/python3.12/site-packages/kafka/record/memory_records.py", line 27, in <module>
    from kafka.record.legacy_records import LegacyRecordBatch, LegacyRecordBatchBuilder
  File "/home/airflow/.local/lib/python3.12/site-packages/kafka/record/legacy_records.py", line 50, in <module>
    from kafka.codec import (
  File "/home/airflow/.local/lib/python3.12/site-packages/kafka/codec.py", line 9, in <module>
    from kafka.vendor.six.moves import range
ModuleNotFoundError: No module named 'kafka.vendor.six.moves'
[2024-11-07T00:19:29.129+0000] {processor.py:842} WARNING - No viable dags retrieved from /opt/airflow/dags/airbyte_sync_fluxos.py
[2024-11-07T00:19:29.158+0000] {processor.py:183} INFO - Processing /opt/airflow/dags/airbyte_sync_fluxos.py took 0.189 seconds
[2024-11-07T00:19:59.708+0000] {processor.py:161} INFO - Started process (PID=9177) to work on /opt/airflow/dags/airbyte_sync_fluxos.py
[2024-11-07T00:19:59.710+0000] {processor.py:830} INFO - Processing file /opt/airflow/dags/airbyte_sync_fluxos.py for tasks to queue
[2024-11-07T00:19:59.713+0000] {logging_mixin.py:188} INFO - [2024-11-07T00:19:59.713+0000] {dagbag.py:545} INFO - Filling up the DagBag from /opt/airflow/dags/airbyte_sync_fluxos.py
[2024-11-07T00:19:59.832+0000] {logging_mixin.py:188} INFO - [2024-11-07T00:19:59.822+0000] {dagbag.py:355} ERROR - Failed to import: /opt/airflow/dags/airbyte_sync_fluxos.py
Traceback (most recent call last):
  File "/home/airflow/.local/lib/python3.12/site-packages/airflow/models/dagbag.py", line 351, in parse
    loader.exec_module(new_module)
  File "<frozen importlib._bootstrap_external>", line 995, in exec_module
  File "<frozen importlib._bootstrap>", line 488, in _call_with_frames_removed
  File "/opt/airflow/dags/airbyte_sync_fluxos.py", line 11, in <module>
    from kafka import KafkaConsumer
  File "/home/airflow/.local/lib/python3.12/site-packages/kafka/__init__.py", line 23, in <module>
    from kafka.consumer import KafkaConsumer
  File "/home/airflow/.local/lib/python3.12/site-packages/kafka/consumer/__init__.py", line 3, in <module>
    from kafka.consumer.group import KafkaConsumer
  File "/home/airflow/.local/lib/python3.12/site-packages/kafka/consumer/group.py", line 13, in <module>
    from kafka.consumer.fetcher import Fetcher
  File "/home/airflow/.local/lib/python3.12/site-packages/kafka/consumer/fetcher.py", line 19, in <module>
    from kafka.record import MemoryRecords
  File "/home/airflow/.local/lib/python3.12/site-packages/kafka/record/__init__.py", line 1, in <module>
    from kafka.record.memory_records import MemoryRecords, MemoryRecordsBuilder
  File "/home/airflow/.local/lib/python3.12/site-packages/kafka/record/memory_records.py", line 27, in <module>
    from kafka.record.legacy_records import LegacyRecordBatch, LegacyRecordBatchBuilder
  File "/home/airflow/.local/lib/python3.12/site-packages/kafka/record/legacy_records.py", line 50, in <module>
    from kafka.codec import (
  File "/home/airflow/.local/lib/python3.12/site-packages/kafka/codec.py", line 9, in <module>
    from kafka.vendor.six.moves import range
ModuleNotFoundError: No module named 'kafka.vendor.six.moves'
[2024-11-07T00:19:59.835+0000] {processor.py:842} WARNING - No viable dags retrieved from /opt/airflow/dags/airbyte_sync_fluxos.py
[2024-11-07T00:19:59.930+0000] {processor.py:183} INFO - Processing /opt/airflow/dags/airbyte_sync_fluxos.py took 0.234 seconds
[2024-11-07T00:20:30.391+0000] {processor.py:161} INFO - Started process (PID=9199) to work on /opt/airflow/dags/airbyte_sync_fluxos.py
[2024-11-07T00:20:30.393+0000] {processor.py:830} INFO - Processing file /opt/airflow/dags/airbyte_sync_fluxos.py for tasks to queue
[2024-11-07T00:20:30.398+0000] {logging_mixin.py:188} INFO - [2024-11-07T00:20:30.397+0000] {dagbag.py:545} INFO - Filling up the DagBag from /opt/airflow/dags/airbyte_sync_fluxos.py
[2024-11-07T00:20:30.535+0000] {logging_mixin.py:188} INFO - [2024-11-07T00:20:30.526+0000] {dagbag.py:355} ERROR - Failed to import: /opt/airflow/dags/airbyte_sync_fluxos.py
Traceback (most recent call last):
  File "/home/airflow/.local/lib/python3.12/site-packages/airflow/models/dagbag.py", line 351, in parse
    loader.exec_module(new_module)
  File "<frozen importlib._bootstrap_external>", line 995, in exec_module
  File "<frozen importlib._bootstrap>", line 488, in _call_with_frames_removed
  File "/opt/airflow/dags/airbyte_sync_fluxos.py", line 11, in <module>
    from kafka import KafkaConsumer
  File "/home/airflow/.local/lib/python3.12/site-packages/kafka/__init__.py", line 23, in <module>
    from kafka.consumer import KafkaConsumer
  File "/home/airflow/.local/lib/python3.12/site-packages/kafka/consumer/__init__.py", line 3, in <module>
    from kafka.consumer.group import KafkaConsumer
  File "/home/airflow/.local/lib/python3.12/site-packages/kafka/consumer/group.py", line 13, in <module>
    from kafka.consumer.fetcher import Fetcher
  File "/home/airflow/.local/lib/python3.12/site-packages/kafka/consumer/fetcher.py", line 19, in <module>
    from kafka.record import MemoryRecords
  File "/home/airflow/.local/lib/python3.12/site-packages/kafka/record/__init__.py", line 1, in <module>
    from kafka.record.memory_records import MemoryRecords, MemoryRecordsBuilder
  File "/home/airflow/.local/lib/python3.12/site-packages/kafka/record/memory_records.py", line 27, in <module>
    from kafka.record.legacy_records import LegacyRecordBatch, LegacyRecordBatchBuilder
  File "/home/airflow/.local/lib/python3.12/site-packages/kafka/record/legacy_records.py", line 50, in <module>
    from kafka.codec import (
  File "/home/airflow/.local/lib/python3.12/site-packages/kafka/codec.py", line 9, in <module>
    from kafka.vendor.six.moves import range
ModuleNotFoundError: No module named 'kafka.vendor.six.moves'
[2024-11-07T00:20:30.536+0000] {processor.py:842} WARNING - No viable dags retrieved from /opt/airflow/dags/airbyte_sync_fluxos.py
[2024-11-07T00:20:30.568+0000] {processor.py:183} INFO - Processing /opt/airflow/dags/airbyte_sync_fluxos.py took 0.188 seconds
[2024-11-07T00:21:01.018+0000] {processor.py:161} INFO - Started process (PID=9228) to work on /opt/airflow/dags/airbyte_sync_fluxos.py
[2024-11-07T00:21:01.022+0000] {processor.py:830} INFO - Processing file /opt/airflow/dags/airbyte_sync_fluxos.py for tasks to queue
[2024-11-07T00:21:01.038+0000] {logging_mixin.py:188} INFO - [2024-11-07T00:21:01.036+0000] {dagbag.py:545} INFO - Filling up the DagBag from /opt/airflow/dags/airbyte_sync_fluxos.py
[2024-11-07T00:21:01.356+0000] {logging_mixin.py:188} INFO - [2024-11-07T00:21:01.344+0000] {dagbag.py:355} ERROR - Failed to import: /opt/airflow/dags/airbyte_sync_fluxos.py
Traceback (most recent call last):
  File "/home/airflow/.local/lib/python3.12/site-packages/airflow/models/dagbag.py", line 351, in parse
    loader.exec_module(new_module)
  File "<frozen importlib._bootstrap_external>", line 995, in exec_module
  File "<frozen importlib._bootstrap>", line 488, in _call_with_frames_removed
  File "/opt/airflow/dags/airbyte_sync_fluxos.py", line 11, in <module>
    from kafka import KafkaConsumer
  File "/home/airflow/.local/lib/python3.12/site-packages/kafka/__init__.py", line 23, in <module>
    from kafka.consumer import KafkaConsumer
  File "/home/airflow/.local/lib/python3.12/site-packages/kafka/consumer/__init__.py", line 3, in <module>
    from kafka.consumer.group import KafkaConsumer
  File "/home/airflow/.local/lib/python3.12/site-packages/kafka/consumer/group.py", line 13, in <module>
    from kafka.consumer.fetcher import Fetcher
  File "/home/airflow/.local/lib/python3.12/site-packages/kafka/consumer/fetcher.py", line 19, in <module>
    from kafka.record import MemoryRecords
  File "/home/airflow/.local/lib/python3.12/site-packages/kafka/record/__init__.py", line 1, in <module>
    from kafka.record.memory_records import MemoryRecords, MemoryRecordsBuilder
  File "/home/airflow/.local/lib/python3.12/site-packages/kafka/record/memory_records.py", line 27, in <module>
    from kafka.record.legacy_records import LegacyRecordBatch, LegacyRecordBatchBuilder
  File "/home/airflow/.local/lib/python3.12/site-packages/kafka/record/legacy_records.py", line 50, in <module>
    from kafka.codec import (
  File "/home/airflow/.local/lib/python3.12/site-packages/kafka/codec.py", line 9, in <module>
    from kafka.vendor.six.moves import range
ModuleNotFoundError: No module named 'kafka.vendor.six.moves'
[2024-11-07T00:21:01.358+0000] {processor.py:842} WARNING - No viable dags retrieved from /opt/airflow/dags/airbyte_sync_fluxos.py
[2024-11-07T00:21:01.392+0000] {processor.py:183} INFO - Processing /opt/airflow/dags/airbyte_sync_fluxos.py took 0.401 seconds
[2024-11-07T00:21:31.877+0000] {processor.py:161} INFO - Started process (PID=9251) to work on /opt/airflow/dags/airbyte_sync_fluxos.py
[2024-11-07T00:21:31.879+0000] {processor.py:830} INFO - Processing file /opt/airflow/dags/airbyte_sync_fluxos.py for tasks to queue
[2024-11-07T00:21:31.882+0000] {logging_mixin.py:188} INFO - [2024-11-07T00:21:31.881+0000] {dagbag.py:545} INFO - Filling up the DagBag from /opt/airflow/dags/airbyte_sync_fluxos.py
[2024-11-07T00:21:32.015+0000] {logging_mixin.py:188} INFO - [2024-11-07T00:21:32.007+0000] {dagbag.py:355} ERROR - Failed to import: /opt/airflow/dags/airbyte_sync_fluxos.py
Traceback (most recent call last):
  File "/home/airflow/.local/lib/python3.12/site-packages/airflow/models/dagbag.py", line 351, in parse
    loader.exec_module(new_module)
  File "<frozen importlib._bootstrap_external>", line 995, in exec_module
  File "<frozen importlib._bootstrap>", line 488, in _call_with_frames_removed
  File "/opt/airflow/dags/airbyte_sync_fluxos.py", line 11, in <module>
    from kafka import KafkaConsumer
  File "/home/airflow/.local/lib/python3.12/site-packages/kafka/__init__.py", line 23, in <module>
    from kafka.consumer import KafkaConsumer
  File "/home/airflow/.local/lib/python3.12/site-packages/kafka/consumer/__init__.py", line 3, in <module>
    from kafka.consumer.group import KafkaConsumer
  File "/home/airflow/.local/lib/python3.12/site-packages/kafka/consumer/group.py", line 13, in <module>
    from kafka.consumer.fetcher import Fetcher
  File "/home/airflow/.local/lib/python3.12/site-packages/kafka/consumer/fetcher.py", line 19, in <module>
    from kafka.record import MemoryRecords
  File "/home/airflow/.local/lib/python3.12/site-packages/kafka/record/__init__.py", line 1, in <module>
    from kafka.record.memory_records import MemoryRecords, MemoryRecordsBuilder
  File "/home/airflow/.local/lib/python3.12/site-packages/kafka/record/memory_records.py", line 27, in <module>
    from kafka.record.legacy_records import LegacyRecordBatch, LegacyRecordBatchBuilder
  File "/home/airflow/.local/lib/python3.12/site-packages/kafka/record/legacy_records.py", line 50, in <module>
    from kafka.codec import (
  File "/home/airflow/.local/lib/python3.12/site-packages/kafka/codec.py", line 9, in <module>
    from kafka.vendor.six.moves import range
ModuleNotFoundError: No module named 'kafka.vendor.six.moves'
[2024-11-07T00:21:32.016+0000] {processor.py:842} WARNING - No viable dags retrieved from /opt/airflow/dags/airbyte_sync_fluxos.py
[2024-11-07T00:21:32.040+0000] {processor.py:183} INFO - Processing /opt/airflow/dags/airbyte_sync_fluxos.py took 0.173 seconds
[2024-11-07T00:22:02.483+0000] {processor.py:161} INFO - Started process (PID=9273) to work on /opt/airflow/dags/airbyte_sync_fluxos.py
[2024-11-07T00:22:02.486+0000] {processor.py:830} INFO - Processing file /opt/airflow/dags/airbyte_sync_fluxos.py for tasks to queue
[2024-11-07T00:22:02.489+0000] {logging_mixin.py:188} INFO - [2024-11-07T00:22:02.489+0000] {dagbag.py:545} INFO - Filling up the DagBag from /opt/airflow/dags/airbyte_sync_fluxos.py
[2024-11-07T00:22:02.607+0000] {logging_mixin.py:188} INFO - [2024-11-07T00:22:02.599+0000] {dagbag.py:355} ERROR - Failed to import: /opt/airflow/dags/airbyte_sync_fluxos.py
Traceback (most recent call last):
  File "/home/airflow/.local/lib/python3.12/site-packages/airflow/models/dagbag.py", line 351, in parse
    loader.exec_module(new_module)
  File "<frozen importlib._bootstrap_external>", line 995, in exec_module
  File "<frozen importlib._bootstrap>", line 488, in _call_with_frames_removed
  File "/opt/airflow/dags/airbyte_sync_fluxos.py", line 11, in <module>
    from kafka import KafkaConsumer
  File "/home/airflow/.local/lib/python3.12/site-packages/kafka/__init__.py", line 23, in <module>
    from kafka.consumer import KafkaConsumer
  File "/home/airflow/.local/lib/python3.12/site-packages/kafka/consumer/__init__.py", line 3, in <module>
    from kafka.consumer.group import KafkaConsumer
  File "/home/airflow/.local/lib/python3.12/site-packages/kafka/consumer/group.py", line 13, in <module>
    from kafka.consumer.fetcher import Fetcher
  File "/home/airflow/.local/lib/python3.12/site-packages/kafka/consumer/fetcher.py", line 19, in <module>
    from kafka.record import MemoryRecords
  File "/home/airflow/.local/lib/python3.12/site-packages/kafka/record/__init__.py", line 1, in <module>
    from kafka.record.memory_records import MemoryRecords, MemoryRecordsBuilder
  File "/home/airflow/.local/lib/python3.12/site-packages/kafka/record/memory_records.py", line 27, in <module>
    from kafka.record.legacy_records import LegacyRecordBatch, LegacyRecordBatchBuilder
  File "/home/airflow/.local/lib/python3.12/site-packages/kafka/record/legacy_records.py", line 50, in <module>
    from kafka.codec import (
  File "/home/airflow/.local/lib/python3.12/site-packages/kafka/codec.py", line 9, in <module>
    from kafka.vendor.six.moves import range
ModuleNotFoundError: No module named 'kafka.vendor.six.moves'
[2024-11-07T00:22:02.609+0000] {processor.py:842} WARNING - No viable dags retrieved from /opt/airflow/dags/airbyte_sync_fluxos.py
[2024-11-07T00:22:02.681+0000] {processor.py:183} INFO - Processing /opt/airflow/dags/airbyte_sync_fluxos.py took 0.206 seconds
[2024-11-07T00:22:33.153+0000] {processor.py:161} INFO - Started process (PID=9295) to work on /opt/airflow/dags/airbyte_sync_fluxos.py
[2024-11-07T00:22:33.154+0000] {processor.py:830} INFO - Processing file /opt/airflow/dags/airbyte_sync_fluxos.py for tasks to queue
[2024-11-07T00:22:33.158+0000] {logging_mixin.py:188} INFO - [2024-11-07T00:22:33.157+0000] {dagbag.py:545} INFO - Filling up the DagBag from /opt/airflow/dags/airbyte_sync_fluxos.py
[2024-11-07T00:22:33.343+0000] {logging_mixin.py:188} INFO - [2024-11-07T00:22:33.330+0000] {dagbag.py:355} ERROR - Failed to import: /opt/airflow/dags/airbyte_sync_fluxos.py
Traceback (most recent call last):
  File "/home/airflow/.local/lib/python3.12/site-packages/airflow/models/dagbag.py", line 351, in parse
    loader.exec_module(new_module)
  File "<frozen importlib._bootstrap_external>", line 995, in exec_module
  File "<frozen importlib._bootstrap>", line 488, in _call_with_frames_removed
  File "/opt/airflow/dags/airbyte_sync_fluxos.py", line 11, in <module>
    from kafka import KafkaConsumer
  File "/home/airflow/.local/lib/python3.12/site-packages/kafka/__init__.py", line 23, in <module>
    from kafka.consumer import KafkaConsumer
  File "/home/airflow/.local/lib/python3.12/site-packages/kafka/consumer/__init__.py", line 3, in <module>
    from kafka.consumer.group import KafkaConsumer
  File "/home/airflow/.local/lib/python3.12/site-packages/kafka/consumer/group.py", line 13, in <module>
    from kafka.consumer.fetcher import Fetcher
  File "/home/airflow/.local/lib/python3.12/site-packages/kafka/consumer/fetcher.py", line 19, in <module>
    from kafka.record import MemoryRecords
  File "/home/airflow/.local/lib/python3.12/site-packages/kafka/record/__init__.py", line 1, in <module>
    from kafka.record.memory_records import MemoryRecords, MemoryRecordsBuilder
  File "/home/airflow/.local/lib/python3.12/site-packages/kafka/record/memory_records.py", line 27, in <module>
    from kafka.record.legacy_records import LegacyRecordBatch, LegacyRecordBatchBuilder
  File "/home/airflow/.local/lib/python3.12/site-packages/kafka/record/legacy_records.py", line 50, in <module>
    from kafka.codec import (
  File "/home/airflow/.local/lib/python3.12/site-packages/kafka/codec.py", line 9, in <module>
    from kafka.vendor.six.moves import range
ModuleNotFoundError: No module named 'kafka.vendor.six.moves'
[2024-11-07T00:22:33.399+0000] {processor.py:842} WARNING - No viable dags retrieved from /opt/airflow/dags/airbyte_sync_fluxos.py
[2024-11-07T00:22:33.427+0000] {processor.py:183} INFO - Processing /opt/airflow/dags/airbyte_sync_fluxos.py took 0.284 seconds
[2024-11-07T00:23:03.893+0000] {processor.py:161} INFO - Started process (PID=9317) to work on /opt/airflow/dags/airbyte_sync_fluxos.py
[2024-11-07T00:23:03.895+0000] {processor.py:830} INFO - Processing file /opt/airflow/dags/airbyte_sync_fluxos.py for tasks to queue
[2024-11-07T00:23:03.898+0000] {logging_mixin.py:188} INFO - [2024-11-07T00:23:03.897+0000] {dagbag.py:545} INFO - Filling up the DagBag from /opt/airflow/dags/airbyte_sync_fluxos.py
[2024-11-07T00:23:04.018+0000] {logging_mixin.py:188} INFO - [2024-11-07T00:23:04.007+0000] {dagbag.py:355} ERROR - Failed to import: /opt/airflow/dags/airbyte_sync_fluxos.py
Traceback (most recent call last):
  File "/home/airflow/.local/lib/python3.12/site-packages/airflow/models/dagbag.py", line 351, in parse
    loader.exec_module(new_module)
  File "<frozen importlib._bootstrap_external>", line 995, in exec_module
  File "<frozen importlib._bootstrap>", line 488, in _call_with_frames_removed
  File "/opt/airflow/dags/airbyte_sync_fluxos.py", line 11, in <module>
    from kafka import KafkaConsumer
  File "/home/airflow/.local/lib/python3.12/site-packages/kafka/__init__.py", line 23, in <module>
    from kafka.consumer import KafkaConsumer
  File "/home/airflow/.local/lib/python3.12/site-packages/kafka/consumer/__init__.py", line 3, in <module>
    from kafka.consumer.group import KafkaConsumer
  File "/home/airflow/.local/lib/python3.12/site-packages/kafka/consumer/group.py", line 13, in <module>
    from kafka.consumer.fetcher import Fetcher
  File "/home/airflow/.local/lib/python3.12/site-packages/kafka/consumer/fetcher.py", line 19, in <module>
    from kafka.record import MemoryRecords
  File "/home/airflow/.local/lib/python3.12/site-packages/kafka/record/__init__.py", line 1, in <module>
    from kafka.record.memory_records import MemoryRecords, MemoryRecordsBuilder
  File "/home/airflow/.local/lib/python3.12/site-packages/kafka/record/memory_records.py", line 27, in <module>
    from kafka.record.legacy_records import LegacyRecordBatch, LegacyRecordBatchBuilder
  File "/home/airflow/.local/lib/python3.12/site-packages/kafka/record/legacy_records.py", line 50, in <module>
    from kafka.codec import (
  File "/home/airflow/.local/lib/python3.12/site-packages/kafka/codec.py", line 9, in <module>
    from kafka.vendor.six.moves import range
ModuleNotFoundError: No module named 'kafka.vendor.six.moves'
[2024-11-07T00:23:04.019+0000] {processor.py:842} WARNING - No viable dags retrieved from /opt/airflow/dags/airbyte_sync_fluxos.py
[2024-11-07T00:23:04.045+0000] {processor.py:183} INFO - Processing /opt/airflow/dags/airbyte_sync_fluxos.py took 0.162 seconds
[2024-11-07T00:23:34.513+0000] {processor.py:161} INFO - Started process (PID=9339) to work on /opt/airflow/dags/airbyte_sync_fluxos.py
[2024-11-07T00:23:34.515+0000] {processor.py:830} INFO - Processing file /opt/airflow/dags/airbyte_sync_fluxos.py for tasks to queue
[2024-11-07T00:23:34.517+0000] {logging_mixin.py:188} INFO - [2024-11-07T00:23:34.517+0000] {dagbag.py:545} INFO - Filling up the DagBag from /opt/airflow/dags/airbyte_sync_fluxos.py
[2024-11-07T00:23:34.625+0000] {logging_mixin.py:188} INFO - [2024-11-07T00:23:34.616+0000] {dagbag.py:355} ERROR - Failed to import: /opt/airflow/dags/airbyte_sync_fluxos.py
Traceback (most recent call last):
  File "/home/airflow/.local/lib/python3.12/site-packages/airflow/models/dagbag.py", line 351, in parse
    loader.exec_module(new_module)
  File "<frozen importlib._bootstrap_external>", line 995, in exec_module
  File "<frozen importlib._bootstrap>", line 488, in _call_with_frames_removed
  File "/opt/airflow/dags/airbyte_sync_fluxos.py", line 11, in <module>
    from kafka import KafkaConsumer
  File "/home/airflow/.local/lib/python3.12/site-packages/kafka/__init__.py", line 23, in <module>
    from kafka.consumer import KafkaConsumer
  File "/home/airflow/.local/lib/python3.12/site-packages/kafka/consumer/__init__.py", line 3, in <module>
    from kafka.consumer.group import KafkaConsumer
  File "/home/airflow/.local/lib/python3.12/site-packages/kafka/consumer/group.py", line 13, in <module>
    from kafka.consumer.fetcher import Fetcher
  File "/home/airflow/.local/lib/python3.12/site-packages/kafka/consumer/fetcher.py", line 19, in <module>
    from kafka.record import MemoryRecords
  File "/home/airflow/.local/lib/python3.12/site-packages/kafka/record/__init__.py", line 1, in <module>
    from kafka.record.memory_records import MemoryRecords, MemoryRecordsBuilder
  File "/home/airflow/.local/lib/python3.12/site-packages/kafka/record/memory_records.py", line 27, in <module>
    from kafka.record.legacy_records import LegacyRecordBatch, LegacyRecordBatchBuilder
  File "/home/airflow/.local/lib/python3.12/site-packages/kafka/record/legacy_records.py", line 50, in <module>
    from kafka.codec import (
  File "/home/airflow/.local/lib/python3.12/site-packages/kafka/codec.py", line 9, in <module>
    from kafka.vendor.six.moves import range
ModuleNotFoundError: No module named 'kafka.vendor.six.moves'
[2024-11-07T00:23:34.627+0000] {processor.py:842} WARNING - No viable dags retrieved from /opt/airflow/dags/airbyte_sync_fluxos.py
[2024-11-07T00:23:34.652+0000] {processor.py:183} INFO - Processing /opt/airflow/dags/airbyte_sync_fluxos.py took 0.147 seconds
[2024-11-07T00:24:05.156+0000] {processor.py:161} INFO - Started process (PID=9361) to work on /opt/airflow/dags/airbyte_sync_fluxos.py
[2024-11-07T00:24:05.157+0000] {processor.py:830} INFO - Processing file /opt/airflow/dags/airbyte_sync_fluxos.py for tasks to queue
[2024-11-07T00:24:05.161+0000] {logging_mixin.py:188} INFO - [2024-11-07T00:24:05.160+0000] {dagbag.py:545} INFO - Filling up the DagBag from /opt/airflow/dags/airbyte_sync_fluxos.py
[2024-11-07T00:24:05.331+0000] {logging_mixin.py:188} INFO - [2024-11-07T00:24:05.320+0000] {dagbag.py:355} ERROR - Failed to import: /opt/airflow/dags/airbyte_sync_fluxos.py
Traceback (most recent call last):
  File "/home/airflow/.local/lib/python3.12/site-packages/airflow/models/dagbag.py", line 351, in parse
    loader.exec_module(new_module)
  File "<frozen importlib._bootstrap_external>", line 995, in exec_module
  File "<frozen importlib._bootstrap>", line 488, in _call_with_frames_removed
  File "/opt/airflow/dags/airbyte_sync_fluxos.py", line 11, in <module>
    from kafka import KafkaConsumer
  File "/home/airflow/.local/lib/python3.12/site-packages/kafka/__init__.py", line 23, in <module>
    from kafka.consumer import KafkaConsumer
  File "/home/airflow/.local/lib/python3.12/site-packages/kafka/consumer/__init__.py", line 3, in <module>
    from kafka.consumer.group import KafkaConsumer
  File "/home/airflow/.local/lib/python3.12/site-packages/kafka/consumer/group.py", line 13, in <module>
    from kafka.consumer.fetcher import Fetcher
  File "/home/airflow/.local/lib/python3.12/site-packages/kafka/consumer/fetcher.py", line 19, in <module>
    from kafka.record import MemoryRecords
  File "/home/airflow/.local/lib/python3.12/site-packages/kafka/record/__init__.py", line 1, in <module>
    from kafka.record.memory_records import MemoryRecords, MemoryRecordsBuilder
  File "/home/airflow/.local/lib/python3.12/site-packages/kafka/record/memory_records.py", line 27, in <module>
    from kafka.record.legacy_records import LegacyRecordBatch, LegacyRecordBatchBuilder
  File "/home/airflow/.local/lib/python3.12/site-packages/kafka/record/legacy_records.py", line 50, in <module>
    from kafka.codec import (
  File "/home/airflow/.local/lib/python3.12/site-packages/kafka/codec.py", line 9, in <module>
    from kafka.vendor.six.moves import range
ModuleNotFoundError: No module named 'kafka.vendor.six.moves'
[2024-11-07T00:24:05.333+0000] {processor.py:842} WARNING - No viable dags retrieved from /opt/airflow/dags/airbyte_sync_fluxos.py
[2024-11-07T00:24:05.435+0000] {processor.py:183} INFO - Processing /opt/airflow/dags/airbyte_sync_fluxos.py took 0.287 seconds
[2024-11-07T00:24:35.902+0000] {processor.py:161} INFO - Started process (PID=9383) to work on /opt/airflow/dags/airbyte_sync_fluxos.py
[2024-11-07T00:24:35.903+0000] {processor.py:830} INFO - Processing file /opt/airflow/dags/airbyte_sync_fluxos.py for tasks to queue
[2024-11-07T00:24:35.906+0000] {logging_mixin.py:188} INFO - [2024-11-07T00:24:35.906+0000] {dagbag.py:545} INFO - Filling up the DagBag from /opt/airflow/dags/airbyte_sync_fluxos.py
[2024-11-07T00:24:36.018+0000] {logging_mixin.py:188} INFO - [2024-11-07T00:24:36.010+0000] {dagbag.py:355} ERROR - Failed to import: /opt/airflow/dags/airbyte_sync_fluxos.py
Traceback (most recent call last):
  File "/home/airflow/.local/lib/python3.12/site-packages/airflow/models/dagbag.py", line 351, in parse
    loader.exec_module(new_module)
  File "<frozen importlib._bootstrap_external>", line 995, in exec_module
  File "<frozen importlib._bootstrap>", line 488, in _call_with_frames_removed
  File "/opt/airflow/dags/airbyte_sync_fluxos.py", line 11, in <module>
    from kafka import KafkaConsumer
  File "/home/airflow/.local/lib/python3.12/site-packages/kafka/__init__.py", line 23, in <module>
    from kafka.consumer import KafkaConsumer
  File "/home/airflow/.local/lib/python3.12/site-packages/kafka/consumer/__init__.py", line 3, in <module>
    from kafka.consumer.group import KafkaConsumer
  File "/home/airflow/.local/lib/python3.12/site-packages/kafka/consumer/group.py", line 13, in <module>
    from kafka.consumer.fetcher import Fetcher
  File "/home/airflow/.local/lib/python3.12/site-packages/kafka/consumer/fetcher.py", line 19, in <module>
    from kafka.record import MemoryRecords
  File "/home/airflow/.local/lib/python3.12/site-packages/kafka/record/__init__.py", line 1, in <module>
    from kafka.record.memory_records import MemoryRecords, MemoryRecordsBuilder
  File "/home/airflow/.local/lib/python3.12/site-packages/kafka/record/memory_records.py", line 27, in <module>
    from kafka.record.legacy_records import LegacyRecordBatch, LegacyRecordBatchBuilder
  File "/home/airflow/.local/lib/python3.12/site-packages/kafka/record/legacy_records.py", line 50, in <module>
    from kafka.codec import (
  File "/home/airflow/.local/lib/python3.12/site-packages/kafka/codec.py", line 9, in <module>
    from kafka.vendor.six.moves import range
ModuleNotFoundError: No module named 'kafka.vendor.six.moves'
[2024-11-07T00:24:36.020+0000] {processor.py:842} WARNING - No viable dags retrieved from /opt/airflow/dags/airbyte_sync_fluxos.py
[2024-11-07T00:24:36.046+0000] {processor.py:183} INFO - Processing /opt/airflow/dags/airbyte_sync_fluxos.py took 0.152 seconds
[2024-11-07T00:25:06.569+0000] {processor.py:161} INFO - Started process (PID=9405) to work on /opt/airflow/dags/airbyte_sync_fluxos.py
[2024-11-07T00:25:06.571+0000] {processor.py:830} INFO - Processing file /opt/airflow/dags/airbyte_sync_fluxos.py for tasks to queue
[2024-11-07T00:25:06.574+0000] {logging_mixin.py:188} INFO - [2024-11-07T00:25:06.574+0000] {dagbag.py:545} INFO - Filling up the DagBag from /opt/airflow/dags/airbyte_sync_fluxos.py
[2024-11-07T00:25:06.711+0000] {logging_mixin.py:188} INFO - [2024-11-07T00:25:06.701+0000] {dagbag.py:355} ERROR - Failed to import: /opt/airflow/dags/airbyte_sync_fluxos.py
Traceback (most recent call last):
  File "/home/airflow/.local/lib/python3.12/site-packages/airflow/models/dagbag.py", line 351, in parse
    loader.exec_module(new_module)
  File "<frozen importlib._bootstrap_external>", line 995, in exec_module
  File "<frozen importlib._bootstrap>", line 488, in _call_with_frames_removed
  File "/opt/airflow/dags/airbyte_sync_fluxos.py", line 11, in <module>
    from kafka import KafkaConsumer
  File "/home/airflow/.local/lib/python3.12/site-packages/kafka/__init__.py", line 23, in <module>
    from kafka.consumer import KafkaConsumer
  File "/home/airflow/.local/lib/python3.12/site-packages/kafka/consumer/__init__.py", line 3, in <module>
    from kafka.consumer.group import KafkaConsumer
  File "/home/airflow/.local/lib/python3.12/site-packages/kafka/consumer/group.py", line 13, in <module>
    from kafka.consumer.fetcher import Fetcher
  File "/home/airflow/.local/lib/python3.12/site-packages/kafka/consumer/fetcher.py", line 19, in <module>
    from kafka.record import MemoryRecords
  File "/home/airflow/.local/lib/python3.12/site-packages/kafka/record/__init__.py", line 1, in <module>
    from kafka.record.memory_records import MemoryRecords, MemoryRecordsBuilder
  File "/home/airflow/.local/lib/python3.12/site-packages/kafka/record/memory_records.py", line 27, in <module>
    from kafka.record.legacy_records import LegacyRecordBatch, LegacyRecordBatchBuilder
  File "/home/airflow/.local/lib/python3.12/site-packages/kafka/record/legacy_records.py", line 50, in <module>
    from kafka.codec import (
  File "/home/airflow/.local/lib/python3.12/site-packages/kafka/codec.py", line 9, in <module>
    from kafka.vendor.six.moves import range
ModuleNotFoundError: No module named 'kafka.vendor.six.moves'
[2024-11-07T00:25:06.713+0000] {processor.py:842} WARNING - No viable dags retrieved from /opt/airflow/dags/airbyte_sync_fluxos.py
[2024-11-07T00:25:06.747+0000] {processor.py:183} INFO - Processing /opt/airflow/dags/airbyte_sync_fluxos.py took 0.186 seconds
[2024-11-07T00:25:37.208+0000] {processor.py:161} INFO - Started process (PID=9427) to work on /opt/airflow/dags/airbyte_sync_fluxos.py
[2024-11-07T00:25:37.210+0000] {processor.py:830} INFO - Processing file /opt/airflow/dags/airbyte_sync_fluxos.py for tasks to queue
[2024-11-07T00:25:37.213+0000] {logging_mixin.py:188} INFO - [2024-11-07T00:25:37.213+0000] {dagbag.py:545} INFO - Filling up the DagBag from /opt/airflow/dags/airbyte_sync_fluxos.py
[2024-11-07T00:25:37.331+0000] {logging_mixin.py:188} INFO - [2024-11-07T00:25:37.320+0000] {dagbag.py:355} ERROR - Failed to import: /opt/airflow/dags/airbyte_sync_fluxos.py
Traceback (most recent call last):
  File "/home/airflow/.local/lib/python3.12/site-packages/airflow/models/dagbag.py", line 351, in parse
    loader.exec_module(new_module)
  File "<frozen importlib._bootstrap_external>", line 995, in exec_module
  File "<frozen importlib._bootstrap>", line 488, in _call_with_frames_removed
  File "/opt/airflow/dags/airbyte_sync_fluxos.py", line 11, in <module>
    from kafka import KafkaConsumer
  File "/home/airflow/.local/lib/python3.12/site-packages/kafka/__init__.py", line 23, in <module>
    from kafka.consumer import KafkaConsumer
  File "/home/airflow/.local/lib/python3.12/site-packages/kafka/consumer/__init__.py", line 3, in <module>
    from kafka.consumer.group import KafkaConsumer
  File "/home/airflow/.local/lib/python3.12/site-packages/kafka/consumer/group.py", line 13, in <module>
    from kafka.consumer.fetcher import Fetcher
  File "/home/airflow/.local/lib/python3.12/site-packages/kafka/consumer/fetcher.py", line 19, in <module>
    from kafka.record import MemoryRecords
  File "/home/airflow/.local/lib/python3.12/site-packages/kafka/record/__init__.py", line 1, in <module>
    from kafka.record.memory_records import MemoryRecords, MemoryRecordsBuilder
  File "/home/airflow/.local/lib/python3.12/site-packages/kafka/record/memory_records.py", line 27, in <module>
    from kafka.record.legacy_records import LegacyRecordBatch, LegacyRecordBatchBuilder
  File "/home/airflow/.local/lib/python3.12/site-packages/kafka/record/legacy_records.py", line 50, in <module>
    from kafka.codec import (
  File "/home/airflow/.local/lib/python3.12/site-packages/kafka/codec.py", line 9, in <module>
    from kafka.vendor.six.moves import range
ModuleNotFoundError: No module named 'kafka.vendor.six.moves'
[2024-11-07T00:25:37.332+0000] {processor.py:842} WARNING - No viable dags retrieved from /opt/airflow/dags/airbyte_sync_fluxos.py
[2024-11-07T00:25:37.361+0000] {processor.py:183} INFO - Processing /opt/airflow/dags/airbyte_sync_fluxos.py took 0.160 seconds
[2024-11-07T00:26:07.793+0000] {processor.py:161} INFO - Started process (PID=9449) to work on /opt/airflow/dags/airbyte_sync_fluxos.py
[2024-11-07T00:26:07.795+0000] {processor.py:830} INFO - Processing file /opt/airflow/dags/airbyte_sync_fluxos.py for tasks to queue
[2024-11-07T00:26:07.798+0000] {logging_mixin.py:188} INFO - [2024-11-07T00:26:07.797+0000] {dagbag.py:545} INFO - Filling up the DagBag from /opt/airflow/dags/airbyte_sync_fluxos.py
[2024-11-07T00:26:07.911+0000] {logging_mixin.py:188} INFO - [2024-11-07T00:26:07.904+0000] {dagbag.py:355} ERROR - Failed to import: /opt/airflow/dags/airbyte_sync_fluxos.py
Traceback (most recent call last):
  File "/home/airflow/.local/lib/python3.12/site-packages/airflow/models/dagbag.py", line 351, in parse
    loader.exec_module(new_module)
  File "<frozen importlib._bootstrap_external>", line 995, in exec_module
  File "<frozen importlib._bootstrap>", line 488, in _call_with_frames_removed
  File "/opt/airflow/dags/airbyte_sync_fluxos.py", line 11, in <module>
    from kafka import KafkaConsumer
  File "/home/airflow/.local/lib/python3.12/site-packages/kafka/__init__.py", line 23, in <module>
    from kafka.consumer import KafkaConsumer
  File "/home/airflow/.local/lib/python3.12/site-packages/kafka/consumer/__init__.py", line 3, in <module>
    from kafka.consumer.group import KafkaConsumer
  File "/home/airflow/.local/lib/python3.12/site-packages/kafka/consumer/group.py", line 13, in <module>
    from kafka.consumer.fetcher import Fetcher
  File "/home/airflow/.local/lib/python3.12/site-packages/kafka/consumer/fetcher.py", line 19, in <module>
    from kafka.record import MemoryRecords
  File "/home/airflow/.local/lib/python3.12/site-packages/kafka/record/__init__.py", line 1, in <module>
    from kafka.record.memory_records import MemoryRecords, MemoryRecordsBuilder
  File "/home/airflow/.local/lib/python3.12/site-packages/kafka/record/memory_records.py", line 27, in <module>
    from kafka.record.legacy_records import LegacyRecordBatch, LegacyRecordBatchBuilder
  File "/home/airflow/.local/lib/python3.12/site-packages/kafka/record/legacy_records.py", line 50, in <module>
    from kafka.codec import (
  File "/home/airflow/.local/lib/python3.12/site-packages/kafka/codec.py", line 9, in <module>
    from kafka.vendor.six.moves import range
ModuleNotFoundError: No module named 'kafka.vendor.six.moves'
[2024-11-07T00:26:07.912+0000] {processor.py:842} WARNING - No viable dags retrieved from /opt/airflow/dags/airbyte_sync_fluxos.py
[2024-11-07T00:26:07.932+0000] {processor.py:183} INFO - Processing /opt/airflow/dags/airbyte_sync_fluxos.py took 0.152 seconds
[2024-11-07T00:26:38.420+0000] {processor.py:161} INFO - Started process (PID=9471) to work on /opt/airflow/dags/airbyte_sync_fluxos.py
[2024-11-07T00:26:38.421+0000] {processor.py:830} INFO - Processing file /opt/airflow/dags/airbyte_sync_fluxos.py for tasks to queue
[2024-11-07T00:26:38.425+0000] {logging_mixin.py:188} INFO - [2024-11-07T00:26:38.424+0000] {dagbag.py:545} INFO - Filling up the DagBag from /opt/airflow/dags/airbyte_sync_fluxos.py
[2024-11-07T00:26:38.528+0000] {logging_mixin.py:188} INFO - [2024-11-07T00:26:38.519+0000] {dagbag.py:355} ERROR - Failed to import: /opt/airflow/dags/airbyte_sync_fluxos.py
Traceback (most recent call last):
  File "/home/airflow/.local/lib/python3.12/site-packages/airflow/models/dagbag.py", line 351, in parse
    loader.exec_module(new_module)
  File "<frozen importlib._bootstrap_external>", line 995, in exec_module
  File "<frozen importlib._bootstrap>", line 488, in _call_with_frames_removed
  File "/opt/airflow/dags/airbyte_sync_fluxos.py", line 11, in <module>
    from kafka import KafkaConsumer
  File "/home/airflow/.local/lib/python3.12/site-packages/kafka/__init__.py", line 23, in <module>
    from kafka.consumer import KafkaConsumer
  File "/home/airflow/.local/lib/python3.12/site-packages/kafka/consumer/__init__.py", line 3, in <module>
    from kafka.consumer.group import KafkaConsumer
  File "/home/airflow/.local/lib/python3.12/site-packages/kafka/consumer/group.py", line 13, in <module>
    from kafka.consumer.fetcher import Fetcher
  File "/home/airflow/.local/lib/python3.12/site-packages/kafka/consumer/fetcher.py", line 19, in <module>
    from kafka.record import MemoryRecords
  File "/home/airflow/.local/lib/python3.12/site-packages/kafka/record/__init__.py", line 1, in <module>
    from kafka.record.memory_records import MemoryRecords, MemoryRecordsBuilder
  File "/home/airflow/.local/lib/python3.12/site-packages/kafka/record/memory_records.py", line 27, in <module>
    from kafka.record.legacy_records import LegacyRecordBatch, LegacyRecordBatchBuilder
  File "/home/airflow/.local/lib/python3.12/site-packages/kafka/record/legacy_records.py", line 50, in <module>
    from kafka.codec import (
  File "/home/airflow/.local/lib/python3.12/site-packages/kafka/codec.py", line 9, in <module>
    from kafka.vendor.six.moves import range
ModuleNotFoundError: No module named 'kafka.vendor.six.moves'
[2024-11-07T00:26:38.530+0000] {processor.py:842} WARNING - No viable dags retrieved from /opt/airflow/dags/airbyte_sync_fluxos.py
[2024-11-07T00:26:38.557+0000] {processor.py:183} INFO - Processing /opt/airflow/dags/airbyte_sync_fluxos.py took 0.147 seconds
[2024-11-07T00:27:09.020+0000] {processor.py:161} INFO - Started process (PID=9493) to work on /opt/airflow/dags/airbyte_sync_fluxos.py
[2024-11-07T00:27:09.022+0000] {processor.py:830} INFO - Processing file /opt/airflow/dags/airbyte_sync_fluxos.py for tasks to queue
[2024-11-07T00:27:09.026+0000] {logging_mixin.py:188} INFO - [2024-11-07T00:27:09.025+0000] {dagbag.py:545} INFO - Filling up the DagBag from /opt/airflow/dags/airbyte_sync_fluxos.py
[2024-11-07T00:27:09.123+0000] {logging_mixin.py:188} INFO - [2024-11-07T00:27:09.113+0000] {dagbag.py:355} ERROR - Failed to import: /opt/airflow/dags/airbyte_sync_fluxos.py
Traceback (most recent call last):
  File "/home/airflow/.local/lib/python3.12/site-packages/airflow/models/dagbag.py", line 351, in parse
    loader.exec_module(new_module)
  File "<frozen importlib._bootstrap_external>", line 995, in exec_module
  File "<frozen importlib._bootstrap>", line 488, in _call_with_frames_removed
  File "/opt/airflow/dags/airbyte_sync_fluxos.py", line 11, in <module>
    from kafka import KafkaConsumer
  File "/home/airflow/.local/lib/python3.12/site-packages/kafka/__init__.py", line 23, in <module>
    from kafka.consumer import KafkaConsumer
  File "/home/airflow/.local/lib/python3.12/site-packages/kafka/consumer/__init__.py", line 3, in <module>
    from kafka.consumer.group import KafkaConsumer
  File "/home/airflow/.local/lib/python3.12/site-packages/kafka/consumer/group.py", line 13, in <module>
    from kafka.consumer.fetcher import Fetcher
  File "/home/airflow/.local/lib/python3.12/site-packages/kafka/consumer/fetcher.py", line 19, in <module>
    from kafka.record import MemoryRecords
  File "/home/airflow/.local/lib/python3.12/site-packages/kafka/record/__init__.py", line 1, in <module>
    from kafka.record.memory_records import MemoryRecords, MemoryRecordsBuilder
  File "/home/airflow/.local/lib/python3.12/site-packages/kafka/record/memory_records.py", line 27, in <module>
    from kafka.record.legacy_records import LegacyRecordBatch, LegacyRecordBatchBuilder
  File "/home/airflow/.local/lib/python3.12/site-packages/kafka/record/legacy_records.py", line 50, in <module>
    from kafka.codec import (
  File "/home/airflow/.local/lib/python3.12/site-packages/kafka/codec.py", line 9, in <module>
    from kafka.vendor.six.moves import range
ModuleNotFoundError: No module named 'kafka.vendor.six.moves'
[2024-11-07T00:27:09.125+0000] {processor.py:842} WARNING - No viable dags retrieved from /opt/airflow/dags/airbyte_sync_fluxos.py
[2024-11-07T00:27:09.150+0000] {processor.py:183} INFO - Processing /opt/airflow/dags/airbyte_sync_fluxos.py took 0.145 seconds
[2024-11-07T00:27:39.621+0000] {processor.py:161} INFO - Started process (PID=9515) to work on /opt/airflow/dags/airbyte_sync_fluxos.py
[2024-11-07T00:27:39.624+0000] {processor.py:830} INFO - Processing file /opt/airflow/dags/airbyte_sync_fluxos.py for tasks to queue
[2024-11-07T00:27:39.629+0000] {logging_mixin.py:188} INFO - [2024-11-07T00:27:39.628+0000] {dagbag.py:545} INFO - Filling up the DagBag from /opt/airflow/dags/airbyte_sync_fluxos.py
[2024-11-07T00:27:39.854+0000] {logging_mixin.py:188} INFO - [2024-11-07T00:27:39.844+0000] {dagbag.py:355} ERROR - Failed to import: /opt/airflow/dags/airbyte_sync_fluxos.py
Traceback (most recent call last):
  File "/home/airflow/.local/lib/python3.12/site-packages/airflow/models/dagbag.py", line 351, in parse
    loader.exec_module(new_module)
  File "<frozen importlib._bootstrap_external>", line 995, in exec_module
  File "<frozen importlib._bootstrap>", line 488, in _call_with_frames_removed
  File "/opt/airflow/dags/airbyte_sync_fluxos.py", line 11, in <module>
    from kafka import KafkaConsumer
  File "/home/airflow/.local/lib/python3.12/site-packages/kafka/__init__.py", line 23, in <module>
    from kafka.consumer import KafkaConsumer
  File "/home/airflow/.local/lib/python3.12/site-packages/kafka/consumer/__init__.py", line 3, in <module>
    from kafka.consumer.group import KafkaConsumer
  File "/home/airflow/.local/lib/python3.12/site-packages/kafka/consumer/group.py", line 13, in <module>
    from kafka.consumer.fetcher import Fetcher
  File "/home/airflow/.local/lib/python3.12/site-packages/kafka/consumer/fetcher.py", line 19, in <module>
    from kafka.record import MemoryRecords
  File "/home/airflow/.local/lib/python3.12/site-packages/kafka/record/__init__.py", line 1, in <module>
    from kafka.record.memory_records import MemoryRecords, MemoryRecordsBuilder
  File "/home/airflow/.local/lib/python3.12/site-packages/kafka/record/memory_records.py", line 27, in <module>
    from kafka.record.legacy_records import LegacyRecordBatch, LegacyRecordBatchBuilder
  File "/home/airflow/.local/lib/python3.12/site-packages/kafka/record/legacy_records.py", line 50, in <module>
    from kafka.codec import (
  File "/home/airflow/.local/lib/python3.12/site-packages/kafka/codec.py", line 9, in <module>
    from kafka.vendor.six.moves import range
ModuleNotFoundError: No module named 'kafka.vendor.six.moves'
[2024-11-07T00:27:39.856+0000] {processor.py:842} WARNING - No viable dags retrieved from /opt/airflow/dags/airbyte_sync_fluxos.py
[2024-11-07T00:27:39.887+0000] {processor.py:183} INFO - Processing /opt/airflow/dags/airbyte_sync_fluxos.py took 0.280 seconds
[2024-11-07T00:28:10.815+0000] {processor.py:161} INFO - Started process (PID=9537) to work on /opt/airflow/dags/airbyte_sync_fluxos.py
[2024-11-07T00:28:10.818+0000] {processor.py:830} INFO - Processing file /opt/airflow/dags/airbyte_sync_fluxos.py for tasks to queue
[2024-11-07T00:28:10.828+0000] {logging_mixin.py:188} INFO - [2024-11-07T00:28:10.827+0000] {dagbag.py:545} INFO - Filling up the DagBag from /opt/airflow/dags/airbyte_sync_fluxos.py
[2024-11-07T00:28:11.217+0000] {logging_mixin.py:188} INFO - [2024-11-07T00:28:11.202+0000] {dagbag.py:355} ERROR - Failed to import: /opt/airflow/dags/airbyte_sync_fluxos.py
Traceback (most recent call last):
  File "/home/airflow/.local/lib/python3.12/site-packages/airflow/models/dagbag.py", line 351, in parse
    loader.exec_module(new_module)
  File "<frozen importlib._bootstrap_external>", line 995, in exec_module
  File "<frozen importlib._bootstrap>", line 488, in _call_with_frames_removed
  File "/opt/airflow/dags/airbyte_sync_fluxos.py", line 11, in <module>
    from kafka import KafkaConsumer
  File "/home/airflow/.local/lib/python3.12/site-packages/kafka/__init__.py", line 23, in <module>
    from kafka.consumer import KafkaConsumer
  File "/home/airflow/.local/lib/python3.12/site-packages/kafka/consumer/__init__.py", line 3, in <module>
    from kafka.consumer.group import KafkaConsumer
  File "/home/airflow/.local/lib/python3.12/site-packages/kafka/consumer/group.py", line 13, in <module>
    from kafka.consumer.fetcher import Fetcher
  File "/home/airflow/.local/lib/python3.12/site-packages/kafka/consumer/fetcher.py", line 19, in <module>
    from kafka.record import MemoryRecords
  File "/home/airflow/.local/lib/python3.12/site-packages/kafka/record/__init__.py", line 1, in <module>
    from kafka.record.memory_records import MemoryRecords, MemoryRecordsBuilder
  File "/home/airflow/.local/lib/python3.12/site-packages/kafka/record/memory_records.py", line 27, in <module>
    from kafka.record.legacy_records import LegacyRecordBatch, LegacyRecordBatchBuilder
  File "/home/airflow/.local/lib/python3.12/site-packages/kafka/record/legacy_records.py", line 50, in <module>
    from kafka.codec import (
  File "/home/airflow/.local/lib/python3.12/site-packages/kafka/codec.py", line 9, in <module>
    from kafka.vendor.six.moves import range
ModuleNotFoundError: No module named 'kafka.vendor.six.moves'
[2024-11-07T00:28:11.220+0000] {processor.py:842} WARNING - No viable dags retrieved from /opt/airflow/dags/airbyte_sync_fluxos.py
[2024-11-07T00:28:11.286+0000] {processor.py:183} INFO - Processing /opt/airflow/dags/airbyte_sync_fluxos.py took 0.546 seconds
[2024-11-07T00:28:41.863+0000] {processor.py:161} INFO - Started process (PID=9559) to work on /opt/airflow/dags/airbyte_sync_fluxos.py
[2024-11-07T00:28:41.896+0000] {processor.py:830} INFO - Processing file /opt/airflow/dags/airbyte_sync_fluxos.py for tasks to queue
[2024-11-07T00:28:41.901+0000] {logging_mixin.py:188} INFO - [2024-11-07T00:28:41.901+0000] {dagbag.py:545} INFO - Filling up the DagBag from /opt/airflow/dags/airbyte_sync_fluxos.py
[2024-11-07T00:28:42.114+0000] {logging_mixin.py:188} INFO - [2024-11-07T00:28:42.100+0000] {dagbag.py:355} ERROR - Failed to import: /opt/airflow/dags/airbyte_sync_fluxos.py
Traceback (most recent call last):
  File "/home/airflow/.local/lib/python3.12/site-packages/airflow/models/dagbag.py", line 351, in parse
    loader.exec_module(new_module)
  File "<frozen importlib._bootstrap_external>", line 995, in exec_module
  File "<frozen importlib._bootstrap>", line 488, in _call_with_frames_removed
  File "/opt/airflow/dags/airbyte_sync_fluxos.py", line 11, in <module>
    from kafka import KafkaConsumer
  File "/home/airflow/.local/lib/python3.12/site-packages/kafka/__init__.py", line 23, in <module>
    from kafka.consumer import KafkaConsumer
  File "/home/airflow/.local/lib/python3.12/site-packages/kafka/consumer/__init__.py", line 3, in <module>
    from kafka.consumer.group import KafkaConsumer
  File "/home/airflow/.local/lib/python3.12/site-packages/kafka/consumer/group.py", line 13, in <module>
    from kafka.consumer.fetcher import Fetcher
  File "/home/airflow/.local/lib/python3.12/site-packages/kafka/consumer/fetcher.py", line 19, in <module>
    from kafka.record import MemoryRecords
  File "/home/airflow/.local/lib/python3.12/site-packages/kafka/record/__init__.py", line 1, in <module>
    from kafka.record.memory_records import MemoryRecords, MemoryRecordsBuilder
  File "/home/airflow/.local/lib/python3.12/site-packages/kafka/record/memory_records.py", line 27, in <module>
    from kafka.record.legacy_records import LegacyRecordBatch, LegacyRecordBatchBuilder
  File "/home/airflow/.local/lib/python3.12/site-packages/kafka/record/legacy_records.py", line 50, in <module>
    from kafka.codec import (
  File "/home/airflow/.local/lib/python3.12/site-packages/kafka/codec.py", line 9, in <module>
    from kafka.vendor.six.moves import range
ModuleNotFoundError: No module named 'kafka.vendor.six.moves'
[2024-11-07T00:28:42.116+0000] {processor.py:842} WARNING - No viable dags retrieved from /opt/airflow/dags/airbyte_sync_fluxos.py
[2024-11-07T00:28:42.164+0000] {processor.py:183} INFO - Processing /opt/airflow/dags/airbyte_sync_fluxos.py took 0.314 seconds
